Workbook
Name __123Graph_A_4: #REF!
Name __123Graph_A_4: #REF!
Name __123Graph_A_4: #REF!
Name __123Graph_A_4: #REF!
Name __123Graph_A_4: #REF!
Name __123Graph_A_4: #REF!
Name __123Graph_A_4: #REF!
Name __123Graph_A_4: #REF!
Name __123Graph_A_4: #REF!
Name __123Graph_A_4: #REF!
Name __123Graph_A_4: #REF!
Name __123Graph_A_4: #REF!
Name __123Graph_X_1: #REF!
Name __123Graph_X_1: #REF!
Name __123Graph_X_1: #REF!
Name __123Graph_X_1: #REF!
Name __123Graph_X_1: #REF!
Name __123Graph_X_1: #REF!
Name __123Graph_X_1: #REF!
Name __123Graph_X_1: #REF!
Name __123Graph_X_1: #REF!
Name __123Graph_X_1: #REF!
Name __123Graph_X_1: #REF!
Name __123Graph_X_1: #REF!
Name aaa: #REF!
Name aaa: #REF!
Name aaa: #REF!
Name aaa: #REF!
Name aaa: #REF!
Name aaa: #REF!
Name aaa: #REF!
Name aaa: #REF!
Name aaa: #REF!
Name aaa: #REF!
Name aaa: #REF!
Name aaa: #REF!
Name aaab: #REF!
Name aaab: #REF!
Name aaab: #REF!
Name aaab: #REF!
Name aaab: #REF!
Name aaab: #REF!
Name aaab: #REF!
Name aaab: #REF!
Name aaab: #REF!
Name aaab: #REF!
Name aaab: #REF!
Name aaab: #REF!
Name aaad: #REF!
Name aaad: #REF!
Name aaad: #REF!
Name aaad: #REF!
Name aaad: #REF!
Name aaad: #REF!
Name aaad: #REF!
Name aaad: #REF!
Name aaad: #REF!
Name aaad: #REF!
Name aaad: #REF!
Name aaad: #REF!

Sheet 7.1
G1: JENAYAH KOMERSIAL
G2: COMMERCIAL CRIMES
B5: Jadual 7.1 | C5: : Statistik kes dan kerugian mengikut kesalahan, Malaysia, 2021–2023
B6: Table 7.1 | C6: : Statistics of cases and losses by offence, Malaysia, 2021–2023
B9: Kesalahan Offence | D9: Tahun Year | E9: Bilangan kes Number of cases | F9: Kerugian Losses (RM juta/ RM million)
B11: Jumlah | D11: 2021 | E11: =SUM(E15,E19,E23,E27,E31,E35,E39,E43,E47) -> 31490 | F11: =SUM(F15,F19,F23,F27,F31,F35,F39,F43,F47) -> 2206.4449
B12: Total | D12: 2022 | E12: =SUM(E16,E20,E24,E28,E32,E36,E40,E44,E48) -> 30536 | F12: =SUM(F16,F20,F24,F28,F32,F36,F40,F44,F48) -> 1732.63
D13: 2023 | E13: =SUM(E17,E21,E25,E29,E33,E37,E41,E45,E49) -> 40350 | F13: =SUM(F17,F21,F25,F29,F33,F37,F41,F45,F49) -> 2111.65
B15: Tipu | D15: 2021 | E15: 28842 | F15: 1360.3424
B16: Fraud | D16: 2022 | E16: 27967 | F16: =ROUND(J16/1000000,2) -> 1375.87 | J16: 1.3758708e+09
D17: 2023 | E17: 36936 | F17: =ROUND(J17/1000000,2) -> 1678.08 | J17: 1.6780825e+09
B19: Pecah amanah jenayah | D19: 2021 | E19: 942 | F19: 824.68789
B20: Criminal breach of trust | D20: 2022 | E20: 909 | F20: =ROUND(J20/1000000,2) -> 331.58 | J20: 3.3157808e+08
D21: 2023 | E21: 1217 | F21: =ROUND(J21/1000000,2) -> 381.99 | J21: 3.8198746e+08
B23: Akta Pemberi Pinjam Wang 1951 | D23: 2021 | E23: 847 | F23: 3.8976819
B24: Money Lender Act 1951 | D24: 2022 | E24: 832 | F24: =ROUND(J24/1000000,2) -> 4.94 | J24: 4935188
D25: 2023 | E25: 994 | F25: =ROUND(J25/1000000,2) -> 5.47 | J25: 5472598.3
B27: Jenayah siber | D27: 2021 | E27: 400 | F27: 13.595358
B28: Cyber crime | D28: 2022 | E28: 574 | F28: =ROUND(J28/1000000,2) -> 17.7 | J28: 17699869
D29: 2023 | E29: 869 | F29: =ROUND(J29/1000000,2) -> 35.65 | J29: 35649849
B31: Wang palsu | D31: 2021 | E31: 204 | F31: 0.0503607
B32: Counterfeit money | D32: 2022 | E32: 62 | F32: =ROUND(J32/1000000,2) -> 0.13 | J32: 133746
D33: 2023 | E33: 68 | F33: =ROUND(J33/1000000,2) -> 0.25 | J33: 245330
B35: Pemalsuan | D35: 2021 | E35: 115 | F35: 0.90877999
B36: Forgery | D36: 2022 | E36: 81 | F36: =ROUND(J36/1000000,2) -> 0.45 | J36: 448529
D37: 2023 | E37: 134 | F37: =ROUND(J37/1000000,2) -> 6.87 | J37: 6874030.6
B39: Salah guna harta | D39: 2021 | E39: 57 | F39: 2.9127398
B40: Misuse of property | D40: 2022 | E40: 28 | F40: =ROUND(J40/1000000,2) -> 1.29 | J40: 1287168.4
D41: 2023 | E41: 47 | F41: =ROUND(J41/1000000,2) -> 2.54 | J41: 2542654.6
B43: Kes VCD/ DVD tanpa sijil Ba | D43: 2021 | E43: 21 | F43: -
B44: Case of VCD/ DVD without certificate B | D44: 2022 | E44: 7 | F44: -
D45: 2023 | E45: 15 | F45: -
B47: Lain-lain kesb | D47: 2021 | E47: 62 | F47: 0.04974
B48: Others case | D48: 2022 | E48: 76 | F48: =ROUND(J48/1000000,2) -> 0.67 | J48: 665535.7
D49: 2023 | E49: 70 | F49: =ROUND(J49/1000000,2) -> 0.8 | J49: 795440.96
G51: Sumber: Polis Diraja Malaysia
G52: Source: Royal Malaysia Police
A53: Nota/ Notes:
A54: a Akta Penapisan Filem 2002
A55: Film Censorship Act 2002
...

Sheet 7.2
P2: JENAYAH KOMERSIAL
P3: COMMERCIAL CRIMES
B5: Jadual 7.2 | C5: : Statistik kes dan kerugian jenayah dalam talian, mengikut negeri, Malaysia, 2021–2023
B6: Table 7.2 | C6: : Statistics of cases and losses for online crime by state , Malaysia, 2021–2023
B10: Negeri | D10: Tahun | E10: Jumlah | H10: Jenayah telekomunikasi | K10: E-kewangan | N10: Love scam
B11: State | D11: Year | E11: Total | H11: Telecommunication crime | K11: e-Finance
E12: Kes | F12: RM | H12: Kes | I12: RM | K12: Kes | L12: RM | N12: Kes | O12: RM
E13: Case | H13: Case | K13: Case | N13: Case
B16: MALAYSIA | D16: 2021 | E16: =SUM(H16,K16,N16,'7.2(1)'!E16,'7.2(1)'!H16,'7.2(1)'!K16) -> 26257 | F16: =SUM(I16,L16,O16,'7.2(1)'!F16,'7.2(1)'!I16,'7.2(1)'!L16) -> 6.9843553e+08 | H16: =SUM(H20,H24,H28,H32,H36,H40,H44,H48,H52,H56,H60,H64,H68,H72) -> 6423 | I16: =SUM(I20,I24,I28,I32,I36,I40,I44,I48,I52,I56,I60,I64,I68,I72) -> 1.995503e+08 | K16: =SUM(K20,K24,K28,K32,K36,K40,K44,K48,K52,K56,K60,K64,K68,K72) -> 896 | L16: =SUM(L20,L24,L28,L32,L36,L40,L44,L48,L52,L56,L60,L64,L68,L72) -> 73454968 | N16: =SUM(N20,N24,N28,N32,N36,N40,N44,N48,N52,N56,N60,N64,N68,N72) -> 1460 | O16: =SUM(O20,O24,O28,O32,O36,O40,O44,O48,O52,O56,O60,O64,O68,O72) -> 56743230
D17: 2022 | E17: =SUM(H17,K17,N17,'7.2(1)'!E17,'7.2(1)'!H17,'7.2(1)'!K17) -> 25479 | F17: =SUM(I17,L17,O17,'7.2(1)'!F17,'7.2(1)'!I17,'7.2(1)'!L17) -> 8.5112164e+08 | H17: =SUM(H21,H25,H29,H33,H37,H41,H45,H49,H53,H57,H61,H65,H69,H73) -> 7732 | I17: =SUM(I21,I25,I29,I33,I37,I41,I45,I49,I53,I57,I61,I65,I69,I73) -> 3.2136152e+08 | K17: =SUM(K21,K25,K29,K33,K37,K41,K45,K49,K53,K57,K61,K65,K69,K73) -> 1257 | L17: =SUM(L21,L25,L29,L33,L37,L41,L45,L49,L53,L57,L61,L65,L69,L73) -> 76216960 | N17: =SUM(N21,N25,N29,N33,N37,N41,N45,N49,N53,N57,N61,N65,N69,N73) -> 792 | O17: =SUM(O21,O25,O29,O33,O37,O41,O45,O49,O53,O57,O61,O65,O69,O73) -> 56273794
D18: 2023 | E18: =SUM(H18,K18,N18,'7.2(1)'!E18,'7.2(1)'!H18,'7.2(1)'!K18) -> 34532 | F18: =SUM(I18,L18,O18,'7.2(1)'!F18,'7.2(1)'!I18,'7.2(1)'!L18) -> 1.220302e+09 | H18: =SUM(H22,H26,H30,H34,H38,H42,H46,H50,H54,H58,H62,H66,H70,H74) -> 10368 | I18: =SUM(I22,I26,I30,I34,I38,I42,I46,I50,I54,I58,I62,I66,I70,I74) -> 3.535911e+08 | K18: =SUM(K22,K26,K30,K34,K38,K42,K46,K50,K54,K58,K62,K66,K70,K74) -> 2092 | L18: =SUM(L22,L26,L30,L34,L38,L42,L46,L50,L54,L58,L62,L66,L70,L74) -> 1.0490225e+08 | N18: =SUM(N22,N26,N30,N34,N38,N42,N46,N50,N54,N58,N62,N66,N70,N74) -> 935 | O18: =SUM(O22,O26,O30,O34,O38,O42,O46,O50,O54,O58,O62,O66,O70,O74) -> 43952599
B20: Johor | D20: 2021 | E20: =SUM(H20,K20,N20,'7.2(1)'!E20,'7.2(1)'!H20,'7.2(1)'!K20) -> 2552 | F20: =SUM(I20,L20,O20,'7.2(1)'!F20,'7.2(1)'!I20,'7.2(1)'!L20) -> 64682228 | H20: 646 | I20: 22628755 | K20: 41 | L20: 4018159.2 | N20: 122 | O20: 6455871.7
D21: 2022 | E21: =SUM(H21,K21,N21,'7.2(1)'!E21,'7.2(1)'!H21,'7.2(1)'!K21) -> 2407 | F21: =SUM(I21,L21,O21,'7.2(1)'!F21,'7.2(1)'!I21,'7.2(1)'!L21) -> 83188640 | H21: 708 | I21: 31099151 | K21: 128 | L21: 4916561.5 | N21: 77 | O21: 7624895
D22: 2023 | E22: =SUM(H22,K22,N22,'7.2(1)'!E22,'7.2(1)'!H22,'7.2(1)'!K22) -> 3737 | F22: =SUM(I22,L22,O22,'7.2(1)'!F22,'7.2(1)'!I22,'7.2(1)'!L22) -> 1.2909493e+08 | H22: 1052 | I22: 32688628 | K22: 349 | L22: 17314164 | N22: 91 | O22: 3506281.9
B24: Kedah | D24: 2021 | E24: =SUM(H24,K24,N24,'7.2(1)'!E24,'7.2(1)'!H24,'7.2(1)'!K24) -> 1642 | F24: =SUM(I24,L24,O24,'7.2(1)'!F24,'7.2(1)'!I24,'7.2(1)'!L24) -> 23850424 | H24: 373 | I24: 6572857.3 | K24: 53 | L24: 401430.31 | N24: 98 | O24: 2361385
D25: 2022 | E25: =SUM(H25,K25,N25,'7.2(1)'!E25,'7.2(1)'!H25,'7.2(1)'!K25) -> 1577 | F25: =SUM(I25,L25,O25,'7.2(1)'!F25,'7.2(1)'!I25,'7.2(1)'!L25) -> 46223539 | H25: 474 | I25: 18784796 | K25: 56 | L25: 6076062.4 | N25: 56 | O25: 2467609
D26: 2023 | E26: =SUM(H26,K26,N26,'7.2(1)'!E26,'7.2(1)'!H26,'7.2(1)'!K26) -> 1919 | F26: =SUM(I26,L26,O26,'7.2(1)'!F26,'7.2(1)'!I26,'7.2(1)'!L26) -> 42208991 | H26: 553 | I26: 13862168 | K26: 105 | L26: 3010117.6 | N26: 81 | O26: 1578447
B28: Kelantan | D28: 2021 | E28: =SUM(H28,K28,N28,'7.2(1)'!E28,'7.2(1)'!H28,'7.2(1)'!K28) -> 792 | F28: =SUM(I28,L28,O28,'7.2(1)'!F28,'7.2(1)'!I28,'7.2(1)'!L28) -> 11270326 | H28: 131 | I28: 3626626.4 | K28: 41 | L28: 853052.27 | N28: 50 | O28: 1263000
D29: 2022 | E29: =SUM(H29,K29,N29,'7.2(1)'!E29,'7.2(1)'!H29,'7.2(1)'!K29) -> 886 | F29: =SUM(I29,L29,O29,'7.2(1)'!F29,'7.2(1)'!I29,'7.2(1)'!L29) -> 18230721 | H29: 267 | I29: 7309277.9 | K29: 48 | L29: 1097218.3 | N29: 29 | O29: 1009104.1
D30: 2023 | E30: =SUM(H30,K30,N30,'7.2(1)'!E30,'7.2(1)'!H30,'7.2(1)'!K30) -> 947 | F30: =SUM(I30,L30,O30,'7.2(1)'!F30,'7.2(1)'!I30,'7.2(1)'!L30) -> 28800208 | H30: 323 | I30: 15031876 | K30: 45 | L30: 925969.85 | N30: 28 | O30: 1062035.4
B32: Melaka | D32: 2021 | E32: =SUM(H32,K32,N32,'7.2(1)'!E32,'7.2(1)'!H32,'7.2(1)'!K32) -> 1098 | F32: =SUM(I32,L32,O32,'7.2(1)'!F32,'7.2(1)'!I32,'7.2(1)'!L32) -> 21946536 | H32: 269 | I32: 7976575.2 | K32: 38 | L32: 1273102 | N32: 77 | O32: 2443531.6
D33: 2022 | E33: =SUM(H33,K33,N33,'7.2(1)'!E33,'7.2(1)'!H33,'7.2(1)'!K33) -> 1316 | F33: =SUM(I33,L33,O33,'7.2(1)'!F33,'7.2(1)'!I33,'7.2(1)'!L33) -> 29329780 | H33: 381 | I33: 13288346 | K33: 52 | L33: 2498003.1 | N33: 54 | O33: 1931420
D34: 2023 | E34: =SUM(H34,K34,N34,'7.2(1)'!E34,'7.2(1)'!H34,'7.2(1)'!K34) -> 1573 | F34: =SUM(I34,L34,O34,'7.2(1)'!F34,'7.2(1)'!I34,'7.2(1)'!L34) -> 40571208 | H34: 367 | I34: 9076636.9 | K34: 77 | L34: 1070434.9 | N34: 46 | O34: 730279.43
B36: Negeri Sembilan | D36: 2021 | E36: =SUM(H36,K36,N36,'7.2(1)'!E36,'7.2(1)'!H36,'7.2(1)'!K36) -> 2448 | F36: =SUM(I36,L36,O36,'7.2(1)'!F36,'7.2(1)'!I36,'7.2(1)'!L36) -> 28146639 | H36: 565 | I36: 8757613.8 | K36: 95 | L36: 1030951.7 | N36: 116 | O36: 1819840.2
D37: 2022 | E37: =SUM(H37,K37,N37,'7.2(1)'!E37,'7.2(1)'!H37,'7.2(1)'!K37) -> 2501 | F37: =SUM(I37,L37,O37,'7.2(1)'!F37,'7.2(1)'!I37,'7.2(1)'!L37) -> 42878203 | H37: 883 | I37: 18334999 | K37: 133 | L37: 5624101.9 | N37: 74 | O37: 1836809.5
D38: 2023 | E38: =SUM(H38,K38,N38,'7.2(1)'!E38,'7.2(1)'!H38,'7.2(1)'!K38) -> 2705 | F38: =SUM(I38,L38,O38,'7.2(1)'!F38,'7.2(1)'!I38,'7.2(1)'!L38) -> 48162590 | H38: 708 | I38: 14104185 | K38: 156 | L38: 1898518.3 | N38: 81 | O38: 2638996
B40: Pahang | D40: 2021 | E40: =SUM(H40,K40,N40,'7.2(1)'!E40,'7.2(1)'!H40,'7.2(1)'!K40) -> 1531 | F40: =SUM(I40,L40,O40,'7.2(1)'!F40,'7.2(1)'!I40,'7.2(1)'!L40) -> 25174208 | H40: 285 | I40: 6677995.9 | K40: 33 | L40: 1965364.3 | N40: 88 | O40: 1755377.3
D41: 2022 | E41: =SUM(H41,K41,N41,'7.2(1)'!E41,'7.2(1)'!H41,'7.2(1)'!K41) -> 1813 | F41: =SUM(I41,L41,O41,'7.2(1)'!F41,'7.2(1)'!I41,'7.2(1)'!L41) -> 35224730 | H41: 494 | I41: 11539995 | K41: 48 | L41: 1127520 | N41: 68 | O41: 5539930
D42: 2023 | E42: =SUM(H42,K42,N42,'7.2(1)'!E42,'7.2(1)'!H42,'7.2(1)'!K42) -> 2141 | F42: =SUM(I42,L42,O42,'7.2(1)'!F42,'7.2(1)'!I42,'7.2(1)'!L42) -> 37528973 | H42: 562 | I42: 14468151 | K42: 87 | L42: 1036714.5 | N42: 67 | O42: 1161595.8
B44: Pulau Pinang | D44: 2021 | E44: =SUM(H44,K44,N44,'7.2(1)'!E44,'7.2(1)'!H44,'7.2(1)'!K44) -> 2792 | F44: =SUM(I44,L44,O44,'7.2(1)'!F44,'7.2(1)'!I44,'7.2(1)'!L44) -> 89563618 | H44: 829 | I44: 19010422 | K44: 66 | L44: 11484089 | N44: 132 | O44: 4748743
D45: 2022 | E45: =SUM(H45,K45,N45,'7.2(1)'!E45,'7.2(1)'!H45,'7.2(1)'!K45) -> 2240 | F45: =SUM(I45,L45,O45,'7.2(1)'!F45,'7.2(1)'!I45,'7.2(1)'!L45) -> 80254645 | H45: 718 | I45: 23679229 | K45: 93 | L45: 19671657 | N45: 52 | O45: 6338727
D46: 2023 | E46: =SUM(H46,K46,N46,'7.2(1)'!E46,'7.2(1)'!H46,'7.2(1)'!K46) -> 3011 | F46: =SUM(I46,L46,O46,'7.2(1)'!F46,'7.2(1)'!I46,'7.2(1)'!L46) -> 99925847 | H46: 949 | I46: 34731162 | K46: 134 | L46: 2466463.9 | N46: 73 | O46: 2914846.1
B48: Perak | D48: 2021 | E48: =SUM(H48,K48,N48,'7.2(1)'!E48,'7.2(1)'!H48,'7.2(1)'!K48) -> 1710 | F48: =SUM(I48,L48,O48,'7.2(1)'!F48,'7.2(1)'!I48,'7.2(1)'!L48) -> 39343264 | H48: 432 | I48: 13194619 | K48: 43 | L48: 1612396.6 | N48: 92 | O48: 2963636.3
D49: 2022 | E49: =SUM(H49,K49,N49,'7.2(1)'!E49,'7.2(1)'!H49,'7.2(1)'!K49) -> 1667 | F49: =SUM(I49,L49,O49,'7.2(1)'!F49,'7.2(1)'!I49,'7.2(1)'!L49) -> 43005988 | H49: 535 | I49: 18606755 | K49: 62 | L49: 2016408.3 | N49: 59 | O49: 2613542.6
D50: 2023 | E50: =SUM(H50,K50,N50,'7.2(1)'!E50,'7.2(1)'!H50,'7.2(1)'!K50) -> 2395 | F50: =SUM(I50,L50,O50,'7.2(1)'!F50,'7.2(1)'!I50,'7.2(1)'!L50) -> 63532684 | H50: 733 | I50: 23405393 | K50: 145 | L50: 3867021.6 | N50: 61 | O50: 3318529.6
B52: Perlis | D52: 2021 | E52: =SUM(H52,K52,N52,'7.2(1)'!E52,'7.2(1)'!H52,'7.2(1)'!K52) -> 356 | F52: =SUM(I52,L52,O52,'7.2(1)'!F52,'7.2(1)'!I52,'7.2(1)'!L52) -> 2995232.6 | H52: 77 | I52: 1262194 | K52: 13 | L52: 43133.91 | N52: 26 | O52: 266150
D53: 2022 | E53: =SUM(H53,K53,N53,'7.2(1)'!E53,'7.2(1)'!H53,'7.2(1)'!K53) -> 399 | F53: =SUM(I53,L53,O53,'7.2(1)'!F53,'7.2(1)'!I53,'7.2(1)'!L53) -> 5203154.6 | H53: 110 | I53: 2453566.4 | K53: 29 | L53: 283856.99 | N53: 12 | O53: 119630
D54: 2023 | E54: =SUM(H54,K54,N54,'7.2(1)'!E54,'7.2(1)'!H54,'7.2(1)'!K54) -> 404 | F54: =SUM(I54,L54,O54,'7.2(1)'!F54,'7.2(1)'!I54,'7.2(1)'!L54) -> 5552169.8 | H54: 139 | I54: 1852617.6 | K54: 17 | L54: 191044.26 | N54: 9 | O54: 78050
B56: Selangor | D56: 2021 | E56: =SUM(H56,K56,N56,'7.2(1)'!E56,'7.2(1)'!H56,'7.2(1)'!K56) -> 3439 | F56: =SUM(I56,L56,O56,'7.2(1)'!F56,'7.2(1)'!I56,'7.2(1)'!L56) -> 1.536492e+08 | H56: 820 | I56: 47464687 | K56: 85 | L56: 10925873 | N56: 208 | O56: 14789475
D57: 2022 | E57: =SUM(H57,K57,N57,'7.2(1)'!E57,'7.2(1)'!H57,'7.2(1)'!K57) -> 2850 | F57: =SUM(I57,L57,O57,'7.2(1)'!F57,'7.2(1)'!I57,'7.2(1)'!L57) -> 2.1513962e+08 | H57: 799 | I57: 75895678 | K57: 127 | L57: 13030962 | N57: 97 | O57: 13161139
...

Sheet 7.2(1)
M2: JENAYAH KOMERSIAL
M3: COMMERCIAL CRIMES
B5: Jadual 7.2 | C5: : Statistik kes dan kerugian jenayah dalam talian, mengikut negeri, Malaysia, 2021–2023 (samb.)
B6: Table 7.2 | C6: : Statistics of cases and losses for online crime by state , Malaysia, 2021–2023 (cont'd)
B10: Negeri | D10: Tahun | E10: E-dagang | H10: Pinjaman tidak wujud | K10: Pelaburan tidak wujud
B11: State | D11: Year | E11: e-Commerce | H11: Non-existent loans | K11: Non-existent investments
E12: Kes | F12: RM | H12: Kes | I12: RM | K12: Kes | L12: RM
E13: Case | H13: Case | K13: Case
B16: MALAYSIA | D16: 2021 | E16: =SUM(E20,E24,E28,E32,E36,E40,E44,E48,E52,E56,E60,E64,E68,E72) -> 9499 | F16: =SUM(F20,F24,F28,F32,F36,F40,F44,F48,F52,F56,F60,F64,F68,F72) -> 73027318 | H16: =SUM(H20,H24,H28,H32,H36,H40,H44,H48,H52,H56,H60,H64,H68,H72) -> 4784 | I16: =SUM(I20,I24,I28,I32,I36,I40,I44,I48,I52,I56,I60,I64,I68,I72) -> 50604324 | K16: =SUM(K20,K24,K28,K32,K36,K40,K44,K48,K52,K56,K60,K64,K68,K72) -> 3195 | L16: =SUM(L20,L24,L28,L32,L36,L40,L44,L48,L52,L56,L60,L64,L68,L72) -> 2.4505539e+08
D17: 2022 | E17: =SUM(E21,E25,E29,E33,E37,E41,E45,E49,E53,E57,E61,E65,E69,E73) -> 9258 | F17: =SUM(F21,F25,F29,F33,F37,F41,F45,F49,F53,F57,F61,F65,F69,F73) -> 1.3998581e+08 | H17: =SUM(H21,H25,H29,H33,H37,H41,H45,H49,H53,H57,H61,H65,H69,H73) -> 3174 | I17: =SUM(I21,I25,I29,I33,I37,I41,I45,I49,I53,I57,I61,I65,I69,I73) -> 37447096 | K17: =SUM(K21,K25,K29,K33,K37,K41,K45,K49,K53,K57,K61,K65,K69,K73) -> 3266 | L17: =SUM(L21,L25,L29,L33,L37,L41,L45,L49,L53,L57,L61,L65,L69,L73) -> 2.1983646e+08
D18: 2023 | E18: =SUM(E22,E26,E30,E34,E38,E42,E46,E50,E54,E58,E62,E66,E70,E74) -> 11481 | F18: =SUM(F22,F26,F30,F34,F38,F42,F46,F50,F54,F58,F62,F66,F70,F74) -> 2.0426411e+08 | H18: =SUM(H22,H26,H30,H34,H38,H42,H46,H50,H54,H58,H62,H66,H70,H74) -> 4263 | I18: =SUM(I22,I26,I30,I34,I38,I42,I46,I50,I54,I58,I62,I66,I70,I74) -> 40762816 | K18: =SUM(K22,K26,K30,K34,K38,K42,K46,K50,K54,K58,K62,K66,K70,K74) -> 5393 | L18: =SUM(L22,L26,L30,L34,L38,L42,L46,L50,L54,L58,L62,L66,L70,L74) -> 4.7282907e+08
B20: Johor | D20: 2021 | E20: 844 | F20: 8977727.1 | H20: 516 | I20: 6285023.7 | K20: 383 | L20: 16316691
D21: 2022 | E21: 889 | F21: 16552901 | H21: 299 | I21: 3518799.6 | K21: 306 | L21: 19476331
D22: 2023 | E22: 1117 | F22: 20707759 | H22: 511 | I22: 5308987.2 | K22: 617 | L22: 49569113
B24: Kedah | D24: 2021 | E24: 599 | F24: 3717342.3 | H24: 299 | I24: 2855183.8 | K24: 220 | L24: 7942224.8
D25: 2022 | E25: 545 | F25: 7765761.6 | H25: 216 | I25: 2565361.4 | K25: 230 | L25: 8563948.2
D26: 2023 | E26: 573 | F26: 6914626.2 | H26: 281 | I26: 2719240.2 | K26: 326 | L26: 14124391
B28: Kelantan | D28: 2021 | E28: 350 | F28: 1978331.5 | H28: 130 | I28: 1376485.3 | K28: 90 | L28: 2172830.1
D29: 2022 | E29: 298 | F29: 3732594.2 | H29: 109 | I29: 879092.54 | K29: 135 | L29: 4203434.4
D30: 2023 | E30: 308 | F30: 3184169.5 | H30: 95 | I30: 1100363 | K30: 148 | L30: 7495794.1
B32: Melaka | D32: 2021 | E32: 340 | F32: 2882936.3 | H32: 211 | I32: 2113148.3 | K32: 163 | L32: 5257242.2
D33: 2022 | E33: 469 | F33: 4967247.2 | H33: 180 | I33: 1537540.6 | K33: 180 | L33: 5107222.7
D34: 2023 | E34: 528 | F34: 5963514.6 | H34: 259 | I34: 1885451.3 | K34: 296 | L34: 21844891
B36: Negeri Sembilan | D36: 2021 | E36: 1002 | F36: 4302590.6 | H36: 439 | I36: 3737114.3 | K36: 231 | L36: 8498528
D37: 2022 | E37: 751 | F37: 5849898 | H37: 336 | I37: 2518375.8 | K37: 324 | L37: 8714018.9
D38: 2023 | E38: 971 | F38: 9788820 | H38: 389 | I38: 2595406.8 | K38: 400 | L38: 17136665
B40: Pahang | D40: 2021 | E40: 633 | F40: 4436502.3 | H40: 331 | I40: 3043532.8 | K40: 161 | L40: 7295434.9
D41: 2022 | E41: 707 | F41: 7621167.9 | H41: 253 | I41: 3127424.9 | K41: 243 | L41: 6268691.8
D42: 2023 | E42: 742 | F42: 8068364 | H42: 322 | I42: 2267573.3 | K42: 361 | L42: 10526575
B44: Pulau Pinang | D44: 2021 | E44: 958 | F44: 7484766.6 | H44: 405 | I44: 4640735.7 | K44: 402 | L44: 42194862
D45: 2022 | E45: 839 | F45: 14731560 | H45: 261 | I45: 2748468.7 | K45: 277 | L45: 13085003
D46: 2023 | E46: 1017 | F46: 16707838 | H46: 376 | I46: 3753189.3 | K46: 462 | L46: 39352348
B48: Perak | D48: 2021 | E48: 657 | F48: 4928469.3 | H48: 287 | I48: 3223203 | K48: 199 | L48: 13420940
D49: 2022 | E49: 612 | F49: 8236097.7 | H49: 200 | I49: 2214339.7 | K49: 199 | L49: 9318845.4
D50: 2023 | E50: 750 | F50: 9452105.1 | H50: 320 | I50: 3018670 | K50: 386 | L50: 20470965
B52: Perlis | D52: 2021 | E52: 151 | F52: 417945.41 | H52: 49 | I52: 401416.81 | K52: 40 | L52: 604392.45
D53: 2022 | E53: 147 | F53: 1392777 | H53: 53 | I53: 324186.17 | K53: 48 | L53: 629138.03
D54: 2023 | E54: 115 | F54: 850620.8 | H54: 62 | I54: 530395.24 | K54: 62 | L54: 2049441.9
B56: Selangor | D56: 2021 | E56: 1202 | F56: 12409165 | H56: 649 | I56: 8251377.6 | K56: 475 | L56: 59808622
D57: 2022 | E57: 1115 | F57: 25054326 | H57: 304 | I57: 6660116.3 | K57: 408 | L57: 81337395
...

Sheet 7.3 
K2: JENAYAH KOMERSIAL
K3: COMMERCIAL CRIMES
B5: Jadual 7.3 | C5: : Statistik mangsa jenayah dalam talian mengikut negeri dan kumpulan umur, Malaysia, 2021–2023
B6: Table 7.3 | C6: : Statistics of victims for online crime by state and age group, Malaysia, 2021–2023
B10: Negeri | D10: Tahun | E10: Jumlah
B11: State | D11: Year | E11: Total
E13: 15-20 | F13: 21-30 | G13: 31-40 | H13: 41-50 | I13: 51-60 | J13: ≥61
B16: MALAYSIA | D16: 2021 | E16: =SUM('7.3 (samb1)'!E16,'7.3 (samb1)'!L16,'7.3 (samb2)'!E16,'7.3 (samb2)'!L16,'7.3 (samb3)'!E16,'7.3 (samb3)'!L16) -> 2108 | F16: =SUM('7.3 (samb1)'!F16,'7.3 (samb1)'!M16,'7.3 (samb2)'!F16,'7.3 (samb2)'!M16,'7.3 (samb3)'!F16,'7.3 (samb3)'!M16) -> 9132 | G16: =SUM('7.3 (samb1)'!G16,'7.3 (samb1)'!N16,'7.3 (samb2)'!G16,'7.3 (samb2)'!N16,'7.3 (samb3)'!G16,'7.3 (samb3)'!N16) -> 6582 | H16: =SUM('7.3 (samb1)'!H16,'7.3 (samb1)'!O16,'7.3 (samb2)'!H16,'7.3 (samb2)'!O16,'7.3 (samb3)'!H16,'7.3 (samb3)'!O16) -> 4440 | I16: =SUM('7.3 (samb1)'!I16,'7.3 (samb1)'!P16,'7.3 (samb2)'!I16,'7.3 (samb2)'!P16,'7.3 (samb3)'!I16,'7.3 (samb3)'!P16) -> 2596 | J16: =SUM('7.3 (samb1)'!J16,'7.3 (samb1)'!Q16,'7.3 (samb2)'!J16,'7.3 (samb2)'!Q16,'7.3 (samb3)'!J16,'7.3 (samb3)'!Q16) -> 1399
D17: 2022 | E17: =SUM('7.3 (samb1)'!E17,'7.3 (samb1)'!L17,'7.3 (samb2)'!E17,'7.3 (samb2)'!L17,'7.3 (samb3)'!E17,'7.3 (samb3)'!L17) -> 1620 | F17: =SUM('7.3 (samb1)'!F17,'7.3 (samb1)'!M17,'7.3 (samb2)'!F17,'7.3 (samb2)'!M17,'7.3 (samb3)'!F17,'7.3 (samb3)'!M17) -> 8428 | G17: =SUM('7.3 (samb1)'!G17,'7.3 (samb1)'!N17,'7.3 (samb2)'!G17,'7.3 (samb2)'!N17,'7.3 (samb3)'!G17,'7.3 (samb3)'!N17) -> 6871 | H17: =SUM('7.3 (samb1)'!H17,'7.3 (samb1)'!O17,'7.3 (samb2)'!H17,'7.3 (samb2)'!O17,'7.3 (samb3)'!H17,'7.3 (samb3)'!O17) -> 4513 | I17: =SUM('7.3 (samb1)'!I17,'7.3 (samb1)'!P17,'7.3 (samb2)'!I17,'7.3 (samb2)'!P17,'7.3 (samb3)'!I17,'7.3 (samb3)'!P17) -> 2598 | J17: =SUM('7.3 (samb1)'!J17,'7.3 (samb1)'!Q17,'7.3 (samb2)'!J17,'7.3 (samb2)'!Q17,'7.3 (samb3)'!J17,'7.3 (samb3)'!Q17) -> 1449
D18: 2023 | E18: =SUM('7.3 (samb1)'!E18,'7.3 (samb1)'!L18,'7.3 (samb2)'!E18,'7.3 (samb2)'!L18,'7.3 (samb3)'!E18,'7.3 (samb3)'!L18) -> 2066 | F18: =SUM('7.3 (samb1)'!F18,'7.3 (samb1)'!M18,'7.3 (samb2)'!F18,'7.3 (samb2)'!M18,'7.3 (samb3)'!F18,'7.3 (samb3)'!M18) -> 10538 | G18: =SUM('7.3 (samb1)'!G18,'7.3 (samb1)'!N18,'7.3 (samb2)'!G18,'7.3 (samb2)'!N18,'7.3 (samb3)'!G18,'7.3 (samb3)'!N18) -> 8928 | H18: =SUM('7.3 (samb1)'!H18,'7.3 (samb1)'!O18,'7.3 (samb2)'!H18,'7.3 (samb2)'!O18,'7.3 (samb3)'!H18,'7.3 (samb3)'!O18) -> 6274 | I18: =SUM('7.3 (samb1)'!I18,'7.3 (samb1)'!P18,'7.3 (samb2)'!I18,'7.3 (samb2)'!P18,'7.3 (samb3)'!I18,'7.3 (samb3)'!P18) -> 4094 | J18: =SUM('7.3 (samb1)'!J18,'7.3 (samb1)'!Q18,'7.3 (samb2)'!J18,'7.3 (samb2)'!Q18,'7.3 (samb3)'!J18,'7.3 (samb3)'!Q18) -> 2595
B20: Johor | D20: 2021 | E20: =SUM('7.3 (samb1)'!E20,'7.3 (samb1)'!L20,'7.3 (samb2)'!E20,'7.3 (samb2)'!L20,'7.3 (samb3)'!E20,'7.3 (samb3)'!L20) -> 194 | F20: =SUM('7.3 (samb1)'!F20,'7.3 (samb1)'!M20,'7.3 (samb2)'!F20,'7.3 (samb2)'!M20,'7.3 (samb3)'!F20,'7.3 (samb3)'!M20) -> 836 | G20: =SUM('7.3 (samb1)'!G20,'7.3 (samb1)'!N20,'7.3 (samb2)'!G20,'7.3 (samb2)'!N20,'7.3 (samb3)'!G20,'7.3 (samb3)'!N20) -> 635 | H20: =SUM('7.3 (samb1)'!H20,'7.3 (samb1)'!O20,'7.3 (samb2)'!H20,'7.3 (samb2)'!O20,'7.3 (samb3)'!H20,'7.3 (samb3)'!O20) -> 475 | I20: =SUM('7.3 (samb1)'!I20,'7.3 (samb1)'!P20,'7.3 (samb2)'!I20,'7.3 (samb2)'!P20,'7.3 (samb3)'!I20,'7.3 (samb3)'!P20) -> 258 | J20: =SUM('7.3 (samb1)'!J20,'7.3 (samb1)'!Q20,'7.3 (samb2)'!J20,'7.3 (samb2)'!Q20,'7.3 (samb3)'!J20,'7.3 (samb3)'!Q20) -> 153
D21: 2022 | E21: =SUM('7.3 (samb1)'!E21,'7.3 (samb1)'!L21,'7.3 (samb2)'!E21,'7.3 (samb2)'!L21,'7.3 (samb3)'!E21,'7.3 (samb3)'!L21) -> 145 | F21: =SUM('7.3 (samb1)'!F21,'7.3 (samb1)'!M21,'7.3 (samb2)'!F21,'7.3 (samb2)'!M21,'7.3 (samb3)'!F21,'7.3 (samb3)'!M21) -> 753 | G21: =SUM('7.3 (samb1)'!G21,'7.3 (samb1)'!N21,'7.3 (samb2)'!G21,'7.3 (samb2)'!N21,'7.3 (samb3)'!G21,'7.3 (samb3)'!N21) -> 612 | H21: =SUM('7.3 (samb1)'!H21,'7.3 (samb1)'!O21,'7.3 (samb2)'!H21,'7.3 (samb2)'!O21,'7.3 (samb3)'!H21,'7.3 (samb3)'!O21) -> 488 | I21: =SUM('7.3 (samb1)'!I21,'7.3 (samb1)'!P21,'7.3 (samb2)'!I21,'7.3 (samb2)'!P21,'7.3 (samb3)'!I21,'7.3 (samb3)'!P21) -> 264 | J21: =SUM('7.3 (samb1)'!J21,'7.3 (samb1)'!Q21,'7.3 (samb2)'!J21,'7.3 (samb2)'!Q21,'7.3 (samb3)'!J21,'7.3 (samb3)'!Q21) -> 145
D22: 2023 | E22: =SUM('7.3 (samb1)'!E22,'7.3 (samb1)'!L22,'7.3 (samb2)'!E22,'7.3 (samb2)'!L22,'7.3 (samb3)'!E22,'7.3 (samb3)'!L22) -> 204 | F22: =SUM('7.3 (samb1)'!F22,'7.3 (samb1)'!M22,'7.3 (samb2)'!F22,'7.3 (samb2)'!M22,'7.3 (samb3)'!F22,'7.3 (samb3)'!M22) -> 1147 | G22: =SUM('7.3 (samb1)'!G22,'7.3 (samb1)'!N22,'7.3 (samb2)'!G22,'7.3 (samb2)'!N22,'7.3 (samb3)'!G22,'7.3 (samb3)'!N22) -> 946 | H22: =SUM('7.3 (samb1)'!H22,'7.3 (samb1)'!O22,'7.3 (samb2)'!H22,'7.3 (samb2)'!O22,'7.3 (samb3)'!H22,'7.3 (samb3)'!O22) -> 696 | I22: =SUM('7.3 (samb1)'!I22,'7.3 (samb1)'!P22,'7.3 (samb2)'!I22,'7.3 (samb2)'!P22,'7.3 (samb3)'!I22,'7.3 (samb3)'!P22) -> 481 | J22: =SUM('7.3 (samb1)'!J22,'7.3 (samb1)'!Q22,'7.3 (samb2)'!J22,'7.3 (samb2)'!Q22,'7.3 (samb3)'!J22,'7.3 (samb3)'!Q22) -> 261
S23: s
B24: Kedah | D24: 2021 | E24: =SUM('7.3 (samb1)'!E24,'7.3 (samb1)'!L24,'7.3 (samb2)'!E24,'7.3 (samb2)'!L24,'7.3 (samb3)'!E24,'7.3 (samb3)'!L24) -> 150 | F24: =SUM('7.3 (samb1)'!F24,'7.3 (samb1)'!M24,'7.3 (samb2)'!F24,'7.3 (samb2)'!M24,'7.3 (samb3)'!F24,'7.3 (samb3)'!M24) -> 589 | G24: =SUM('7.3 (samb1)'!G24,'7.3 (samb1)'!N24,'7.3 (samb2)'!G24,'7.3 (samb2)'!N24,'7.3 (samb3)'!G24,'7.3 (samb3)'!N24) -> 399 | H24: =SUM('7.3 (samb1)'!H24,'7.3 (samb1)'!O24,'7.3 (samb2)'!H24,'7.3 (samb2)'!O24,'7.3 (samb3)'!H24,'7.3 (samb3)'!O24) -> 263 | I24: =SUM('7.3 (samb1)'!I24,'7.3 (samb1)'!P24,'7.3 (samb2)'!I24,'7.3 (samb2)'!P24,'7.3 (samb3)'!I24,'7.3 (samb3)'!P24) -> 168 | J24: =SUM('7.3 (samb1)'!J24,'7.3 (samb1)'!Q24,'7.3 (samb2)'!J24,'7.3 (samb2)'!Q24,'7.3 (samb3)'!J24,'7.3 (samb3)'!Q24) -> 73
D25: 2022 | E25: =SUM('7.3 (samb1)'!E25,'7.3 (samb1)'!L25,'7.3 (samb2)'!E25,'7.3 (samb2)'!L25,'7.3 (samb3)'!E25,'7.3 (samb3)'!L25) -> 125 | F25: =SUM('7.3 (samb1)'!F25,'7.3 (samb1)'!M25,'7.3 (samb2)'!F25,'7.3 (samb2)'!M25,'7.3 (samb3)'!F25,'7.3 (samb3)'!M25) -> 533 | G25: =SUM('7.3 (samb1)'!G25,'7.3 (samb1)'!N25,'7.3 (samb2)'!G25,'7.3 (samb2)'!N25,'7.3 (samb3)'!G25,'7.3 (samb3)'!N25) -> 387 | H25: =SUM('7.3 (samb1)'!H25,'7.3 (samb1)'!O25,'7.3 (samb2)'!H25,'7.3 (samb2)'!O25,'7.3 (samb3)'!H25,'7.3 (samb3)'!O25) -> 275 | I25: =SUM('7.3 (samb1)'!I25,'7.3 (samb1)'!P25,'7.3 (samb2)'!I25,'7.3 (samb2)'!P25,'7.3 (samb3)'!I25,'7.3 (samb3)'!P25) -> 163 | J25: =SUM('7.3 (samb1)'!J25,'7.3 (samb1)'!Q25,'7.3 (samb2)'!J25,'7.3 (samb2)'!Q25,'7.3 (samb3)'!J25,'7.3 (samb3)'!Q25) -> 94
D26: 2023 | E26: =SUM('7.3 (samb1)'!E26,'7.3 (samb1)'!L26,'7.3 (samb2)'!E26,'7.3 (samb2)'!L26,'7.3 (samb3)'!E26,'7.3 (samb3)'!L26) -> 125 | F26: =SUM('7.3 (samb1)'!F26,'7.3 (samb1)'!M26,'7.3 (samb2)'!F26,'7.3 (samb2)'!M26,'7.3 (samb3)'!F26,'7.3 (samb3)'!M26) -> 589 | G26: =SUM('7.3 (samb1)'!G26,'7.3 (samb1)'!N26,'7.3 (samb2)'!G26,'7.3 (samb2)'!N26,'7.3 (samb3)'!G26,'7.3 (samb3)'!N26) -> 482 | H26: =SUM('7.3 (samb1)'!H26,'7.3 (samb1)'!O26,'7.3 (samb2)'!H26,'7.3 (samb2)'!O26,'7.3 (samb3)'!H26,'7.3 (samb3)'!O26) -> 358 | I26: =SUM('7.3 (samb1)'!I26,'7.3 (samb1)'!P26,'7.3 (samb2)'!I26,'7.3 (samb2)'!P26,'7.3 (samb3)'!I26,'7.3 (samb3)'!P26) -> 232 | J26: =SUM('7.3 (samb1)'!J26,'7.3 (samb1)'!Q26,'7.3 (samb2)'!J26,'7.3 (samb2)'!Q26,'7.3 (samb3)'!J26,'7.3 (samb3)'!Q26) -> 133
B28: Kelantan | D28: 2021 | E28: =SUM('7.3 (samb1)'!E28,'7.3 (samb1)'!L28,'7.3 (samb2)'!E28,'7.3 (samb2)'!L28,'7.3 (samb3)'!E28,'7.3 (samb3)'!L28) -> 99 | F28: =SUM('7.3 (samb1)'!F28,'7.3 (samb1)'!M28,'7.3 (samb2)'!F28,'7.3 (samb2)'!M28,'7.3 (samb3)'!F28,'7.3 (samb3)'!M28) -> 273 | G28: =SUM('7.3 (samb1)'!G28,'7.3 (samb1)'!N28,'7.3 (samb2)'!G28,'7.3 (samb2)'!N28,'7.3 (samb3)'!G28,'7.3 (samb3)'!N28) -> 189 | H28: =SUM('7.3 (samb1)'!H28,'7.3 (samb1)'!O28,'7.3 (samb2)'!H28,'7.3 (samb2)'!O28,'7.3 (samb3)'!H28,'7.3 (samb3)'!O28) -> 131 | I28: =SUM('7.3 (samb1)'!I28,'7.3 (samb1)'!P28,'7.3 (samb2)'!I28,'7.3 (samb2)'!P28,'7.3 (samb3)'!I28,'7.3 (samb3)'!P28) -> 76 | J28: =SUM('7.3 (samb1)'!J28,'7.3 (samb1)'!Q28,'7.3 (samb2)'!J28,'7.3 (samb2)'!Q28,'7.3 (samb3)'!J28,'7.3 (samb3)'!Q28) -> 24
D29: 2022 | E29: =SUM('7.3 (samb1)'!E29,'7.3 (samb1)'!L29,'7.3 (samb2)'!E29,'7.3 (samb2)'!L29,'7.3 (samb3)'!E29,'7.3 (samb3)'!L29) -> 70 | F29: =SUM('7.3 (samb1)'!F29,'7.3 (samb1)'!M29,'7.3 (samb2)'!F29,'7.3 (samb2)'!M29,'7.3 (samb3)'!F29,'7.3 (samb3)'!M29) -> 300 | G29: =SUM('7.3 (samb1)'!G29,'7.3 (samb1)'!N29,'7.3 (samb2)'!G29,'7.3 (samb2)'!N29,'7.3 (samb3)'!G29,'7.3 (samb3)'!N29) -> 224 | H29: =SUM('7.3 (samb1)'!H29,'7.3 (samb1)'!O29,'7.3 (samb2)'!H29,'7.3 (samb2)'!O29,'7.3 (samb3)'!H29,'7.3 (samb3)'!O29) -> 153 | I29: =SUM('7.3 (samb1)'!I29,'7.3 (samb1)'!P29,'7.3 (samb2)'!I29,'7.3 (samb2)'!P29,'7.3 (samb3)'!I29,'7.3 (samb3)'!P29) -> 93 | J29: =SUM('7.3 (samb1)'!J29,'7.3 (samb1)'!Q29,'7.3 (samb2)'!J29,'7.3 (samb2)'!Q29,'7.3 (samb3)'!J29,'7.3 (samb3)'!Q29) -> 46
D30: 2023 | E30: =SUM('7.3 (samb1)'!E30,'7.3 (samb1)'!L30,'7.3 (samb2)'!E30,'7.3 (samb2)'!L30,'7.3 (samb3)'!E30,'7.3 (samb3)'!L30) -> 50 | F30: =SUM('7.3 (samb1)'!F30,'7.3 (samb1)'!M30,'7.3 (samb2)'!F30,'7.3 (samb2)'!M30,'7.3 (samb3)'!F30,'7.3 (samb3)'!M30) -> 271 | G30: =SUM('7.3 (samb1)'!G30,'7.3 (samb1)'!N30,'7.3 (samb2)'!G30,'7.3 (samb2)'!N30,'7.3 (samb3)'!G30,'7.3 (samb3)'!N30) -> 243 | H30: =SUM('7.3 (samb1)'!H30,'7.3 (samb1)'!O30,'7.3 (samb2)'!H30,'7.3 (samb2)'!O30,'7.3 (samb3)'!H30,'7.3 (samb3)'!O30) -> 167 | I30: =SUM('7.3 (samb1)'!I30,'7.3 (samb1)'!P30,'7.3 (samb2)'!I30,'7.3 (samb2)'!P30,'7.3 (samb3)'!I30,'7.3 (samb3)'!P30) -> 121 | J30: =SUM('7.3 (samb1)'!J30,'7.3 (samb1)'!Q30,'7.3 (samb2)'!J30,'7.3 (samb2)'!Q30,'7.3 (samb3)'!J30,'7.3 (samb3)'!Q30) -> 95
B32: Melaka | D32: 2021 | E32: =SUM('7.3 (samb1)'!E32,'7.3 (samb1)'!L32,'7.3 (samb2)'!E32,'7.3 (samb2)'!L32,'7.3 (samb3)'!E32,'7.3 (samb3)'!L32) -> 90 | F32: =SUM('7.3 (samb1)'!F32,'7.3 (samb1)'!M32,'7.3 (samb2)'!F32,'7.3 (samb2)'!M32,'7.3 (samb3)'!F32,'7.3 (samb3)'!M32) -> 360 | G32: =SUM('7.3 (samb1)'!G32,'7.3 (samb1)'!N32,'7.3 (samb2)'!G32,'7.3 (samb2)'!N32,'7.3 (samb3)'!G32,'7.3 (samb3)'!N32) -> 273 | H32: =SUM('7.3 (samb1)'!H32,'7.3 (samb1)'!O32,'7.3 (samb2)'!H32,'7.3 (samb2)'!O32,'7.3 (samb3)'!H32,'7.3 (samb3)'!O32) -> 193 | I32: =SUM('7.3 (samb1)'!I32,'7.3 (samb1)'!P32,'7.3 (samb2)'!I32,'7.3 (samb2)'!P32,'7.3 (samb3)'!I32,'7.3 (samb3)'!P32) -> 108 | J32: =SUM('7.3 (samb1)'!J32,'7.3 (samb1)'!Q32,'7.3 (samb2)'!J32,'7.3 (samb2)'!Q32,'7.3 (samb3)'!J32,'7.3 (samb3)'!Q32) -> 75
D33: 2022 | E33: =SUM('7.3 (samb1)'!E33,'7.3 (samb1)'!L33,'7.3 (samb2)'!E33,'7.3 (samb2)'!L33,'7.3 (samb3)'!E33,'7.3 (samb3)'!L33) -> 91 | F33: =SUM('7.3 (samb1)'!F33,'7.3 (samb1)'!M33,'7.3 (samb2)'!F33,'7.3 (samb2)'!M33,'7.3 (samb3)'!F33,'7.3 (samb3)'!M33) -> 469 | G33: =SUM('7.3 (samb1)'!G33,'7.3 (samb1)'!N33,'7.3 (samb2)'!G33,'7.3 (samb2)'!N33,'7.3 (samb3)'!G33,'7.3 (samb3)'!N33) -> 338 | H33: =SUM('7.3 (samb1)'!H33,'7.3 (samb1)'!O33,'7.3 (samb2)'!H33,'7.3 (samb2)'!O33,'7.3 (samb3)'!H33,'7.3 (samb3)'!O33) -> 211 | I33: =SUM('7.3 (samb1)'!I33,'7.3 (samb1)'!P33,'7.3 (samb2)'!I33,'7.3 (samb2)'!P33,'7.3 (samb3)'!I33,'7.3 (samb3)'!P33) -> 139 | J33: =SUM('7.3 (samb1)'!J33,'7.3 (samb1)'!Q33,'7.3 (samb2)'!J33,'7.3 (samb2)'!Q33,'7.3 (samb3)'!J33,'7.3 (samb3)'!Q33) -> 68
D34: 2023 | E34: =SUM('7.3 (samb1)'!E34,'7.3 (samb1)'!L34,'7.3 (samb2)'!E34,'7.3 (samb2)'!L34,'7.3 (samb3)'!E34,'7.3 (samb3)'!L34) -> 103 | F34: =SUM('7.3 (samb1)'!F34,'7.3 (samb1)'!M34,'7.3 (samb2)'!F34,'7.3 (samb2)'!M34,'7.3 (samb3)'!F34,'7.3 (samb3)'!M34) -> 531 | G34: =SUM('7.3 (samb1)'!G34,'7.3 (samb1)'!N34,'7.3 (samb2)'!G34,'7.3 (samb2)'!N34,'7.3 (samb3)'!G34,'7.3 (samb3)'!N34) -> 395 | H34: =SUM('7.3 (samb1)'!H34,'7.3 (samb1)'!O34,'7.3 (samb2)'!H34,'7.3 (samb2)'!O34,'7.3 (samb3)'!H34,'7.3 (samb3)'!O34) -> 246 | I34: =SUM('7.3 (samb1)'!I34,'7.3 (samb1)'!P34,'7.3 (samb2)'!I34,'7.3 (samb2)'!P34,'7.3 (samb3)'!I34,'7.3 (samb3)'!P34) -> 198 | J34: =SUM('7.3 (samb1)'!J34,'7.3 (samb1)'!Q34,'7.3 (samb2)'!J34,'7.3 (samb2)'!Q34,'7.3 (samb3)'!J34,'7.3 (samb3)'!Q34) -> 100
B36: Negeri Sembilan | D36: 2021 | E36: =SUM('7.3 (samb1)'!E36,'7.3 (samb1)'!L36,'7.3 (samb2)'!E36,'7.3 (samb2)'!L36,'7.3 (samb3)'!E36,'7.3 (samb3)'!L36) -> 236 | F36: =SUM('7.3 (samb1)'!F36,'7.3 (samb1)'!M36,'7.3 (samb2)'!F36,'7.3 (samb2)'!M36,'7.3 (samb3)'!F36,'7.3 (samb3)'!M36) -> 894 | G36: =SUM('7.3 (samb1)'!G36,'7.3 (samb1)'!N36,'7.3 (samb2)'!G36,'7.3 (samb2)'!N36,'7.3 (samb3)'!G36,'7.3 (samb3)'!N36) -> 610 | H36: =SUM('7.3 (samb1)'!H36,'7.3 (samb1)'!O36,'7.3 (samb2)'!H36,'7.3 (samb2)'!O36,'7.3 (samb3)'!H36,'7.3 (samb3)'!O36) -> 397 | I36: =SUM('7.3 (samb1)'!I36,'7.3 (samb1)'!P36,'7.3 (samb2)'!I36,'7.3 (samb2)'!P36,'7.3 (samb3)'!I36,'7.3 (samb3)'!P36) -> 201 | J36: =SUM('7.3 (samb1)'!J36,'7.3 (samb1)'!Q36,'7.3 (samb2)'!J36,'7.3 (samb2)'!Q36,'7.3 (samb3)'!J36,'7.3 (samb3)'!Q36) -> 112
D37: 2022 | E37: =SUM('7.3 (samb1)'!E37,'7.3 (samb1)'!L37,'7.3 (samb2)'!E37,'7.3 (samb2)'!L37,'7.3 (samb3)'!E37,'7.3 (samb3)'!L37) -> 205 | F37: =SUM('7.3 (samb1)'!F37,'7.3 (samb1)'!M37,'7.3 (samb2)'!F37,'7.3 (samb2)'!M37,'7.3 (samb3)'!F37,'7.3 (samb3)'!M37) -> 808 | G37: =SUM('7.3 (samb1)'!G37,'7.3 (samb1)'!N37,'7.3 (samb2)'!G37,'7.3 (samb2)'!N37,'7.3 (samb3)'!G37,'7.3 (samb3)'!N37) -> 653 | H37: =SUM('7.3 (samb1)'!H37,'7.3 (samb1)'!O37,'7.3 (samb2)'!H37,'7.3 (samb2)'!O37,'7.3 (samb3)'!H37,'7.3 (samb3)'!O37) -> 437 | I37: =SUM('7.3 (samb1)'!I37,'7.3 (samb1)'!P37,'7.3 (samb2)'!I37,'7.3 (samb2)'!P37,'7.3 (samb3)'!I37,'7.3 (samb3)'!P37) -> 257 | J37: =SUM('7.3 (samb1)'!J37,'7.3 (samb1)'!Q37,'7.3 (samb2)'!J37,'7.3 (samb2)'!Q37,'7.3 (samb3)'!J37,'7.3 (samb3)'!Q37) -> 141
D38: 2023 | E38: =SUM('7.3 (samb1)'!E38,'7.3 (samb1)'!L38,'7.3 (samb2)'!E38,'7.3 (samb2)'!L38,'7.3 (samb3)'!E38,'7.3 (samb3)'!L38) -> 200 | F38: =SUM('7.3 (samb1)'!F38,'7.3 (samb1)'!M38,'7.3 (samb2)'!F38,'7.3 (samb2)'!M38,'7.3 (samb3)'!F38,'7.3 (samb3)'!M38) -> 799 | G38: =SUM('7.3 (samb1)'!G38,'7.3 (samb1)'!N38,'7.3 (samb2)'!G38,'7.3 (samb2)'!N38,'7.3 (samb3)'!G38,'7.3 (samb3)'!N38) -> 681 | H38: =SUM('7.3 (samb1)'!H38,'7.3 (samb1)'!O38,'7.3 (samb2)'!H38,'7.3 (samb2)'!O38,'7.3 (samb3)'!H38,'7.3 (samb3)'!O38) -> 481 | I38: =SUM('7.3 (samb1)'!I38,'7.3 (samb1)'!P38,'7.3 (samb2)'!I38,'7.3 (samb2)'!P38,'7.3 (samb3)'!I38,'7.3 (samb3)'!P38) -> 324 | J38: =SUM('7.3 (samb1)'!J38,'7.3 (samb1)'!Q38,'7.3 (samb2)'!J38,'7.3 (samb2)'!Q38,'7.3 (samb3)'!J38,'7.3 (samb3)'!Q38) -> 219
B40: Pahang | D40: 2021 | E40: =SUM('7.3 (samb1)'!E40,'7.3 (samb1)'!L40,'7.3 (samb2)'!E40,'7.3 (samb2)'!L40,'7.3 (samb3)'!E40,'7.3 (samb3)'!L40) -> 155 | F40: =SUM('7.3 (samb1)'!F40,'7.3 (samb1)'!M40,'7.3 (samb2)'!F40,'7.3 (samb2)'!M40,'7.3 (samb3)'!F40,'7.3 (samb3)'!M40) -> 537 | G40: =SUM('7.3 (samb1)'!G40,'7.3 (samb1)'!N40,'7.3 (samb2)'!G40,'7.3 (samb2)'!N40,'7.3 (samb3)'!G40,'7.3 (samb3)'!N40) -> 380 | H40: =SUM('7.3 (samb1)'!H40,'7.3 (samb1)'!O40,'7.3 (samb2)'!H40,'7.3 (samb2)'!O40,'7.3 (samb3)'!H40,'7.3 (samb3)'!O40) -> 224 | I40: =SUM('7.3 (samb1)'!I40,'7.3 (samb1)'!P40,'7.3 (samb2)'!I40,'7.3 (samb2)'!P40,'7.3 (samb3)'!I40,'7.3 (samb3)'!P40) -> 163 | J40: =SUM('7.3 (samb1)'!J40,'7.3 (samb1)'!Q40,'7.3 (samb2)'!J40,'7.3 (samb2)'!Q40,'7.3 (samb3)'!J40,'7.3 (samb3)'!Q40) -> 71
D41: 2022 | E41: =SUM('7.3 (samb1)'!E41,'7.3 (samb1)'!L41,'7.3 (samb2)'!E41,'7.3 (samb2)'!L41,'7.3 (samb3)'!E41,'7.3 (samb3)'!L41) -> 117 | F41: =SUM('7.3 (samb1)'!F41,'7.3 (samb1)'!M41,'7.3 (samb2)'!F41,'7.3 (samb2)'!M41,'7.3 (samb3)'!F41,'7.3 (samb3)'!M41) -> 640 | G41: =SUM('7.3 (samb1)'!G41,'7.3 (samb1)'!N41,'7.3 (samb2)'!G41,'7.3 (samb2)'!N41,'7.3 (samb3)'!G41,'7.3 (samb3)'!N41) -> 481 | H41: =SUM('7.3 (samb1)'!H41,'7.3 (samb1)'!O41,'7.3 (samb2)'!H41,'7.3 (samb2)'!O41,'7.3 (samb3)'!H41,'7.3 (samb3)'!O41) -> 318 | I41: =SUM('7.3 (samb1)'!I41,'7.3 (samb1)'!P41,'7.3 (samb2)'!I41,'7.3 (samb2)'!P41,'7.3 (samb3)'!I41,'7.3 (samb3)'!P41) -> 158 | J41: =SUM('7.3 (samb1)'!J41,'7.3 (samb1)'!Q41,'7.3 (samb2)'!J41,'7.3 (samb2)'!Q41,'7.3 (samb3)'!J41,'7.3 (samb3)'!Q41) -> 99
D42: 2023 | E42: =SUM('7.3 (samb1)'!E42,'7.3 (samb1)'!L42,'7.3 (samb2)'!E42,'7.3 (samb2)'!L42,'7.3 (samb3)'!E42,'7.3 (samb3)'!L42) -> 178 | F42: =SUM('7.3 (samb1)'!F42,'7.3 (samb1)'!M42,'7.3 (samb2)'!F42,'7.3 (samb2)'!M42,'7.3 (samb3)'!F42,'7.3 (samb3)'!M42) -> 628 | G42: =SUM('7.3 (samb1)'!G42,'7.3 (samb1)'!N42,'7.3 (samb2)'!G42,'7.3 (samb2)'!N42,'7.3 (samb3)'!G42,'7.3 (samb3)'!N42) -> 605 | H42: =SUM('7.3 (samb1)'!H42,'7.3 (samb1)'!O42,'7.3 (samb2)'!H42,'7.3 (samb2)'!O42,'7.3 (samb3)'!H42,'7.3 (samb3)'!O42) -> 347 | I42: =SUM('7.3 (samb1)'!I42,'7.3 (samb1)'!P42,'7.3 (samb2)'!I42,'7.3 (samb2)'!P42,'7.3 (samb3)'!I42,'7.3 (samb3)'!P42) -> 239 | J42: =SUM('7.3 (samb1)'!J42,'7.3 (samb1)'!Q42,'7.3 (samb2)'!J42,'7.3 (samb2)'!Q42,'7.3 (samb3)'!J42,'7.3 (samb3)'!Q42) -> 144
B44: Pulau Pinang | D44: 2021 | E44: =SUM('7.3 (samb1)'!E44,'7.3 (samb1)'!L44,'7.3 (samb2)'!E44,'7.3 (samb2)'!L44,'7.3 (samb3)'!E44,'7.3 (samb3)'!L44) -> 222 | F44: =SUM('7.3 (samb1)'!F44,'7.3 (samb1)'!M44,'7.3 (samb2)'!F44,'7.3 (samb2)'!M44,'7.3 (samb3)'!F44,'7.3 (samb3)'!M44) -> 1056 | G44: =SUM('7.3 (samb1)'!G44,'7.3 (samb1)'!N44,'7.3 (samb2)'!G44,'7.3 (samb2)'!N44,'7.3 (samb3)'!G44,'7.3 (samb3)'!N44) -> 644 | H44: =SUM('7.3 (samb1)'!H44,'7.3 (samb1)'!O44,'7.3 (samb2)'!H44,'7.3 (samb2)'!O44,'7.3 (samb3)'!H44,'7.3 (samb3)'!O44) -> 449 | I44: =SUM('7.3 (samb1)'!I44,'7.3 (samb1)'!P44,'7.3 (samb2)'!I44,'7.3 (samb2)'!P44,'7.3 (samb3)'!I44,'7.3 (samb3)'!P44) -> 273 | J44: =SUM('7.3 (samb1)'!J44,'7.3 (samb1)'!Q44,'7.3 (samb2)'!J44,'7.3 (samb2)'!Q44,'7.3 (samb3)'!J44,'7.3 (samb3)'!Q44) -> 148
D45: 2022 | E45: =SUM('7.3 (samb1)'!E45,'7.3 (samb1)'!L45,'7.3 (samb2)'!E45,'7.3 (samb2)'!L45,'7.3 (samb3)'!E45,'7.3 (samb3)'!L45) -> 137 | F45: =SUM('7.3 (samb1)'!F45,'7.3 (samb1)'!M45,'7.3 (samb2)'!F45,'7.3 (samb2)'!M45,'7.3 (samb3)'!F45,'7.3 (samb3)'!M45) -> 840 | G45: =SUM('7.3 (samb1)'!G45,'7.3 (samb1)'!N45,'7.3 (samb2)'!G45,'7.3 (samb2)'!N45,'7.3 (samb3)'!G45,'7.3 (samb3)'!N45) -> 537 | H45: =SUM('7.3 (samb1)'!H45,'7.3 (samb1)'!O45,'7.3 (samb2)'!H45,'7.3 (samb2)'!O45,'7.3 (samb3)'!H45,'7.3 (samb3)'!O45) -> 386 | I45: =SUM('7.3 (samb1)'!I45,'7.3 (samb1)'!P45,'7.3 (samb2)'!I45,'7.3 (samb2)'!P45,'7.3 (samb3)'!I45,'7.3 (samb3)'!P45) -> 220 | J45: =SUM('7.3 (samb1)'!J45,'7.3 (samb1)'!Q45,'7.3 (samb2)'!J45,'7.3 (samb2)'!Q45,'7.3 (samb3)'!J45,'7.3 (samb3)'!Q45) -> 120
D46: 2023 | E46: =SUM('7.3 (samb1)'!E46,'7.3 (samb1)'!L46,'7.3 (samb2)'!E46,'7.3 (samb2)'!L46,'7.3 (samb3)'!E46,'7.3 (samb3)'!L46) -> 156 | F46: =SUM('7.3 (samb1)'!F46,'7.3 (samb1)'!M46,'7.3 (samb2)'!F46,'7.3 (samb2)'!M46,'7.3 (samb3)'!F46,'7.3 (samb3)'!M46) -> 1044 | G46: =SUM('7.3 (samb1)'!G46,'7.3 (samb1)'!N46,'7.3 (samb2)'!G46,'7.3 (samb2)'!N46,'7.3 (samb3)'!G46,'7.3 (samb3)'!N46) -> 701 | H46: =SUM('7.3 (samb1)'!H46,'7.3 (samb1)'!O46,'7.3 (samb2)'!H46,'7.3 (samb2)'!O46,'7.3 (samb3)'!H46,'7.3 (samb3)'!O46) -> 589 | I46: =SUM('7.3 (samb1)'!I46,'7.3 (samb1)'!P46,'7.3 (samb2)'!I46,'7.3 (samb2)'!P46,'7.3 (samb3)'!I46,'7.3 (samb3)'!P46) -> 332 | J46: =SUM('7.3 (samb1)'!J46,'7.3 (samb1)'!Q46,'7.3 (samb2)'!J46,'7.3 (samb2)'!Q46,'7.3 (samb3)'!J46,'7.3 (samb3)'!Q46) -> 189
B48: Perak | D48: 2021 | E48: =SUM('7.3 (samb1)'!E48,'7.3 (samb1)'!L48,'7.3 (samb2)'!E48,'7.3 (samb2)'!L48,'7.3 (samb3)'!E48,'7.3 (samb3)'!L48) -> 165 | F48: =SUM('7.3 (samb1)'!F48,'7.3 (samb1)'!M48,'7.3 (samb2)'!F48,'7.3 (samb2)'!M48,'7.3 (samb3)'!F48,'7.3 (samb3)'!M48) -> 578 | G48: =SUM('7.3 (samb1)'!G48,'7.3 (samb1)'!N48,'7.3 (samb2)'!G48,'7.3 (samb2)'!N48,'7.3 (samb3)'!G48,'7.3 (samb3)'!N48) -> 385 | H48: =SUM('7.3 (samb1)'!H48,'7.3 (samb1)'!O48,'7.3 (samb2)'!H48,'7.3 (samb2)'!O48,'7.3 (samb3)'!H48,'7.3 (samb3)'!O48) -> 273 | I48: =SUM('7.3 (samb1)'!I48,'7.3 (samb1)'!P48,'7.3 (samb2)'!I48,'7.3 (samb2)'!P48,'7.3 (samb3)'!I48,'7.3 (samb3)'!P48) -> 181 | J48: =SUM('7.3 (samb1)'!J48,'7.3 (samb1)'!Q48,'7.3 (samb2)'!J48,'7.3 (samb2)'!Q48,'7.3 (samb3)'!J48,'7.3 (samb3)'!Q48) -> 128
D49: 2022 | E49: =SUM('7.3 (samb1)'!E49,'7.3 (samb1)'!L49,'7.3 (samb2)'!E49,'7.3 (samb2)'!L49,'7.3 (samb3)'!E49,'7.3 (samb3)'!L49) -> 130 | F49: =SUM('7.3 (samb1)'!F49,'7.3 (samb1)'!M49,'7.3 (samb2)'!F49,'7.3 (samb2)'!M49,'7.3 (samb3)'!F49,'7.3 (samb3)'!M49) -> 500 | G49: =SUM('7.3 (samb1)'!G49,'7.3 (samb1)'!N49,'7.3 (samb2)'!G49,'7.3 (samb2)'!N49,'7.3 (samb3)'!G49,'7.3 (samb3)'!N49) -> 459 | H49: =SUM('7.3 (samb1)'!H49,'7.3 (samb1)'!O49,'7.3 (samb2)'!H49,'7.3 (samb2)'!O49,'7.3 (samb3)'!H49,'7.3 (samb3)'!O49) -> 293 | I49: =SUM('7.3 (samb1)'!I49,'7.3 (samb1)'!P49,'7.3 (samb2)'!I49,'7.3 (samb2)'!P49,'7.3 (samb3)'!I49,'7.3 (samb3)'!P49) -> 165 | J49: =SUM('7.3 (samb1)'!J49,'7.3 (samb1)'!Q49,'7.3 (samb2)'!J49,'7.3 (samb2)'!Q49,'7.3 (samb3)'!J49,'7.3 (samb3)'!Q49) -> 120
D50: 2023 | E50: =SUM('7.3 (samb1)'!E50,'7.3 (samb1)'!L50,'7.3 (samb2)'!E50,'7.3 (samb2)'!L50,'7.3 (samb3)'!E50,'7.3 (samb3)'!L50) -> 195 | F50: =SUM('7.3 (samb1)'!F50,'7.3 (samb1)'!M50,'7.3 (samb2)'!F50,'7.3 (samb2)'!M50,'7.3 (samb3)'!F50,'7.3 (samb3)'!M50) -> 716 | G50: =SUM('7.3 (samb1)'!G50,'7.3 (samb1)'!N50,'7.3 (samb2)'!G50,'7.3 (samb2)'!N50,'7.3 (samb3)'!G50,'7.3 (samb3)'!N50) -> 512 | H50: =SUM('7.3 (samb1)'!H50,'7.3 (samb1)'!O50,'7.3 (samb2)'!H50,'7.3 (samb2)'!O50,'7.3 (samb3)'!H50,'7.3 (samb3)'!O50) -> 413 | I50: =SUM('7.3 (samb1)'!I50,'7.3 (samb1)'!P50,'7.3 (samb2)'!I50,'7.3 (samb2)'!P50,'7.3 (samb3)'!I50,'7.3 (samb3)'!P50) -> 339 | J50: =SUM('7.3 (samb1)'!J50,'7.3 (samb1)'!Q50,'7.3 (samb2)'!J50,'7.3 (samb2)'!Q50,'7.3 (samb3)'!J50,'7.3 (samb3)'!Q50) -> 219
B52: Perlis | D52: 2021 | E52: =SUM('7.3 (samb1)'!E52,'7.3 (samb1)'!L52,'7.3 (samb2)'!E52,'7.3 (samb2)'!L52,'7.3 (samb3)'!E52,'7.3 (samb3)'!L52) -> 34 | F52: =SUM('7.3 (samb1)'!F52,'7.3 (samb1)'!M52,'7.3 (samb2)'!F52,'7.3 (samb2)'!M52,'7.3 (samb3)'!F52,'7.3 (samb3)'!M52) -> 131 | G52: =SUM('7.3 (samb1)'!G52,'7.3 (samb1)'!N52,'7.3 (samb2)'!G52,'7.3 (samb2)'!N52,'7.3 (samb3)'!G52,'7.3 (samb3)'!N52) -> 80 | H52: =SUM('7.3 (samb1)'!H52,'7.3 (samb1)'!O52,'7.3 (samb2)'!H52,'7.3 (samb2)'!O52,'7.3 (samb3)'!H52,'7.3 (samb3)'!O52) -> 63 | I52: =SUM('7.3 (samb1)'!I52,'7.3 (samb1)'!P52,'7.3 (samb2)'!I52,'7.3 (samb2)'!P52,'7.3 (samb3)'!I52,'7.3 (samb3)'!P52) -> 37 | J52: =SUM('7.3 (samb1)'!J52,'7.3 (samb1)'!Q52,'7.3 (samb2)'!J52,'7.3 (samb2)'!Q52,'7.3 (samb3)'!J52,'7.3 (samb3)'!Q52) -> 12
D53: 2022 | E53: =SUM('7.3 (samb1)'!E53,'7.3 (samb1)'!L53,'7.3 (samb2)'!E53,'7.3 (samb2)'!L53,'7.3 (samb3)'!E53,'7.3 (samb3)'!L53) -> 55 | F53: =SUM('7.3 (samb1)'!F53,'7.3 (samb1)'!M53,'7.3 (samb2)'!F53,'7.3 (samb2)'!M53,'7.3 (samb3)'!F53,'7.3 (samb3)'!M53) -> 129 | G53: =SUM('7.3 (samb1)'!G53,'7.3 (samb1)'!N53,'7.3 (samb2)'!G53,'7.3 (samb2)'!N53,'7.3 (samb3)'!G53,'7.3 (samb3)'!N53) -> 110 | H53: =SUM('7.3 (samb1)'!H53,'7.3 (samb1)'!O53,'7.3 (samb2)'!H53,'7.3 (samb2)'!O53,'7.3 (samb3)'!H53,'7.3 (samb3)'!O53) -> 47 | I53: =SUM('7.3 (samb1)'!I53,'7.3 (samb1)'!P53,'7.3 (samb2)'!I53,'7.3 (samb2)'!P53,'7.3 (samb3)'!I53,'7.3 (samb3)'!P53) -> 44 | J53: =SUM('7.3 (samb1)'!J53,'7.3 (samb1)'!Q53,'7.3 (samb2)'!J53,'7.3 (samb2)'!Q53,'7.3 (samb3)'!J53,'7.3 (samb3)'!Q53) -> 14
D54: 2023 | E54: =SUM('7.3 (samb1)'!E54,'7.3 (samb1)'!L54,'7.3 (samb2)'!E54,'7.3 (samb2)'!L54,'7.3 (samb3)'!E54,'7.3 (samb3)'!L54) -> 51 | F54: =SUM('7.3 (samb1)'!F54,'7.3 (samb1)'!M54,'7.3 (samb2)'!F54,'7.3 (samb2)'!M54,'7.3 (samb3)'!F54,'7.3 (samb3)'!M54) -> 126 | G54: =SUM('7.3 (samb1)'!G54,'7.3 (samb1)'!N54,'7.3 (samb2)'!G54,'7.3 (samb2)'!N54,'7.3 (samb3)'!G54,'7.3 (samb3)'!N54) -> 101 | H54: =SUM('7.3 (samb1)'!H54,'7.3 (samb1)'!O54,'7.3 (samb2)'!H54,'7.3 (samb2)'!O54,'7.3 (samb3)'!H54,'7.3 (samb3)'!O54) -> 62 | I54: =SUM('7.3 (samb1)'!I54,'7.3 (samb1)'!P54,'7.3 (samb2)'!I54,'7.3 (samb2)'!P54,'7.3 (samb3)'!I54,'7.3 (samb3)'!P54) -> 38 | J54: =SUM('7.3 (samb1)'!J54,'7.3 (samb1)'!Q54,'7.3 (samb2)'!J54,'7.3 (samb2)'!Q54,'7.3 (samb3)'!J54,'7.3 (samb3)'!Q54) -> 26
B56: Selangor | D56: 2021 | E56: =SUM('7.3 (samb1)'!E56,'7.3 (samb1)'!L56,'7.3 (samb2)'!E56,'7.3 (samb2)'!L56,'7.3 (samb3)'!E56,'7.3 (samb3)'!L56) -> 194 | F56: =SUM('7.3 (samb1)'!F56,'7.3 (samb1)'!M56,'7.3 (samb2)'!F56,'7.3 (samb2)'!M56,'7.3 (samb3)'!F56,'7.3 (samb3)'!M56) -> 1116 | G56: =SUM('7.3 (samb1)'!G56,'7.3 (samb1)'!N56,'7.3 (samb2)'!G56,'7.3 (samb2)'!N56,'7.3 (samb3)'!G56,'7.3 (samb3)'!N56) -> 915 | H56: =SUM('7.3 (samb1)'!H56,'7.3 (samb1)'!O56,'7.3 (samb2)'!H56,'7.3 (samb2)'!O56,'7.3 (samb3)'!H56,'7.3 (samb3)'!O56) -> 643 | I56: =SUM('7.3 (samb1)'!I56,'7.3 (samb1)'!P56,'7.3 (samb2)'!I56,'7.3 (samb2)'!P56,'7.3 (samb3)'!I56,'7.3 (samb3)'!P56) -> 369 | J56: =SUM('7.3 (samb1)'!J56,'7.3 (samb1)'!Q56,'7.3 (samb2)'!J56,'7.3 (samb2)'!Q56,'7.3 (samb3)'!J56,'7.3 (samb3)'!Q56) -> 200
D57: 2022 | E57: =SUM('7.3 (samb1)'!E57,'7.3 (samb1)'!L57,'7.3 (samb2)'!E57,'7.3 (samb2)'!L57,'7.3 (samb3)'!E57,'7.3 (samb3)'!L57) -> 109 | F57: =SUM('7.3 (samb1)'!F57,'7.3 (samb1)'!M57,'7.3 (samb2)'!F57,'7.3 (samb2)'!M57,'7.3 (samb3)'!F57,'7.3 (samb3)'!M57) -> 890 | G57: =SUM('7.3 (samb1)'!G57,'7.3 (samb1)'!N57,'7.3 (samb2)'!G57,'7.3 (samb2)'!N57,'7.3 (samb3)'!G57,'7.3 (samb3)'!N57) -> 784 | H57: =SUM('7.3 (samb1)'!H57,'7.3 (samb1)'!O57,'7.3 (samb2)'!H57,'7.3 (samb2)'!O57,'7.3 (samb3)'!H57,'7.3 (samb3)'!O57) -> 556 | I57: =SUM('7.3 (samb1)'!I57,'7.3 (samb1)'!P57,'7.3 (samb2)'!I57,'7.3 (samb2)'!P57,'7.3 (samb3)'!I57,'7.3 (samb3)'!P57) -> 355 | J57: =SUM('7.3 (samb1)'!J57,'7.3 (samb1)'!Q57,'7.3 (samb2)'!J57,'7.3 (samb2)'!Q57,'7.3 (samb3)'!J57,'7.3 (samb3)'!Q57) -> 156
...

Sheet 7.3 (samb1)
R2: JENAYAH KOMERSIAL
R3: COMMERCIAL CRIMES
B5: Jadual 7.3 | C5: : Statistik mangsa jenayah dalam talian mengikut negeri dan kumpulan umur, Malaysia, 2021–2023 (samb.)
B6: Table 7.3 | C6: : Statistics of victims for online crime by state and age group, Malaysia, 2021–2023 (cont'd)
B10: Negeri | D10: Tahun | E10: Jenayah telekomunikasi | L10: E-kewangan
B11: State | D11: Year | E11: Telecommunication crime | L11: e-Finance
E13: 15-20 | F13: 21-30 | G13: 31-40 | H13: 41-50 | I13: 51-60 | J13: ≥61 | L13: 15-20 | M13: 21-30 | N13: 31-40 | O13: 41-50 | P13: 51-60 | Q13: ≥61
B16: MALAYSIA | D16: 2021 | E16: =SUM('7.4 (L)'!E16,'7.4 (P)'!E16) -> 337 | F16: =SUM('7.4 (L)'!F16,'7.4 (P)'!F16) -> 1877 | G16: =SUM('7.4 (L)'!G16,'7.4 (P)'!G16) -> 1463 | H16: =SUM('7.4 (L)'!H16,'7.4 (P)'!H16) -> 1112 | I16: =SUM('7.4 (L)'!I16,'7.4 (P)'!I16) -> 882 | J16: =SUM('7.4 (L)'!J16,'7.4 (P)'!J16) -> 752 | L16: =SUM('7.4 (L)'!L16,'7.4 (P)'!L16) -> 65 | M16: =SUM('7.4 (L)'!M16,'7.4 (P)'!M16) -> 262 | N16: =SUM('7.4 (L)'!N16,'7.4 (P)'!N16) -> 193 | O16: =SUM('7.4 (L)'!O16,'7.4 (P)'!O16) -> 163 | P16: =SUM('7.4 (L)'!P16,'7.4 (P)'!P16) -> 143 | Q16: =SUM('7.4 (L)'!Q16,'7.4 (P)'!Q16) -> 70
D17: 2022 | E17: =SUM('7.4 (L)'!E17,'7.4 (P)'!E17) -> 359 | F17: =SUM('7.4 (L)'!F17,'7.4 (P)'!F17) -> 2285 | G17: =SUM('7.4 (L)'!G17,'7.4 (P)'!G17) -> 1893 | H17: =SUM('7.4 (L)'!H17,'7.4 (P)'!H17) -> 1379 | I17: =SUM('7.4 (L)'!I17,'7.4 (P)'!I17) -> 1045 | J17: =SUM('7.4 (L)'!J17,'7.4 (P)'!J17) -> 771 | L17: =SUM('7.4 (L)'!L17,'7.4 (P)'!L17) -> 68 | M17: =SUM('7.4 (L)'!M17,'7.4 (P)'!M17) -> 247 | N17: =SUM('7.4 (L)'!N17,'7.4 (P)'!N17) -> 337 | O17: =SUM('7.4 (L)'!O17,'7.4 (P)'!O17) -> 316 | P17: =SUM('7.4 (L)'!P17,'7.4 (P)'!P17) -> 185 | Q17: =SUM('7.4 (L)'!Q17,'7.4 (P)'!Q17) -> 104
D18: 2023 | E18: =SUM('7.4 (L)'!E18,'7.4 (P)'!E18) -> 657 | F18: =SUM('7.4 (L)'!F18,'7.4 (P)'!F18) -> 3258 | G18: =SUM('7.4 (L)'!G18,'7.4 (P)'!G18) -> 2309 | H18: =SUM('7.4 (L)'!H18,'7.4 (P)'!H18) -> 1714 | I18: =SUM('7.4 (L)'!I18,'7.4 (P)'!I18) -> 1347 | J18: =SUM('7.4 (L)'!J18,'7.4 (P)'!J18) -> 1061 | L18: =SUM('7.4 (L)'!L18,'7.4 (P)'!L18) -> 118 | M18: =SUM('7.4 (L)'!M18,'7.4 (P)'!M18) -> 483 | N18: =SUM('7.4 (L)'!N18,'7.4 (P)'!N18) -> 517 | O18: =SUM('7.4 (L)'!O18,'7.4 (P)'!O18) -> 447 | P18: =SUM('7.4 (L)'!P18,'7.4 (P)'!P18) -> 308 | Q18: =SUM('7.4 (L)'!Q18,'7.4 (P)'!Q18) -> 219 | U18: ≥
B20: Johor | D20: 2021 | E20: =SUM('7.4 (L)'!E20,'7.4 (P)'!E20) -> 38 | F20: =SUM('7.4 (L)'!F20,'7.4 (P)'!F20) -> 153 | G20: =SUM('7.4 (L)'!G20,'7.4 (P)'!G20) -> 137 | H20: =SUM('7.4 (L)'!H20,'7.4 (P)'!H20) -> 138 | I20: =SUM('7.4 (L)'!I20,'7.4 (P)'!I20) -> 91 | J20: =SUM('7.4 (L)'!J20,'7.4 (P)'!J20) -> 89 | L20: =SUM('7.4 (L)'!L20,'7.4 (P)'!L20) -> 2 | M20: =SUM('7.4 (L)'!M20,'7.4 (P)'!M20) -> 14 | N20: =SUM('7.4 (L)'!N20,'7.4 (P)'!N20) -> 7 | O20: =SUM('7.4 (L)'!O20,'7.4 (P)'!O20) -> 6 | P20: =SUM('7.4 (L)'!P20,'7.4 (P)'!P20) -> 9 | Q20: =SUM('7.4 (L)'!Q20,'7.4 (P)'!Q20) -> 3
D21: 2022 | E21: =SUM('7.4 (L)'!E21,'7.4 (P)'!E21) -> 17 | F21: =SUM('7.4 (L)'!F21,'7.4 (P)'!F21) -> 180 | G21: =SUM('7.4 (L)'!G21,'7.4 (P)'!G21) -> 181 | H21: =SUM('7.4 (L)'!H21,'7.4 (P)'!H21) -> 138 | I21: =SUM('7.4 (L)'!I21,'7.4 (P)'!I21) -> 111 | J21: =SUM('7.4 (L)'!J21,'7.4 (P)'!J21) -> 81 | L21: =SUM('7.4 (L)'!L21,'7.4 (P)'!L21) -> 5 | M21: =SUM('7.4 (L)'!M21,'7.4 (P)'!M21) -> 25 | N21: =SUM('7.4 (L)'!N21,'7.4 (P)'!N21) -> 35 | O21: =SUM('7.4 (L)'!O21,'7.4 (P)'!O21) -> 38 | P21: =SUM('7.4 (L)'!P21,'7.4 (P)'!P21) -> 16 | Q21: =SUM('7.4 (L)'!Q21,'7.4 (P)'!Q21) -> 9
D22: 2023 | E22: =SUM('7.4 (L)'!E22,'7.4 (P)'!E22) -> 56 | F22: =SUM('7.4 (L)'!F22,'7.4 (P)'!F22) -> 334 | G22: =SUM('7.4 (L)'!G22,'7.4 (P)'!G22) -> 240 | H22: =SUM('7.4 (L)'!H22,'7.4 (P)'!H22) -> 153 | I22: =SUM('7.4 (L)'!I22,'7.4 (P)'!I22) -> 153 | J22: =SUM('7.4 (L)'!J22,'7.4 (P)'!J22) -> 116 | L22: =SUM('7.4 (L)'!L22,'7.4 (P)'!L22) -> 24 | M22: =SUM('7.4 (L)'!M22,'7.4 (P)'!M22) -> 76 | N22: =SUM('7.4 (L)'!N22,'7.4 (P)'!N22) -> 84 | O22: =SUM('7.4 (L)'!O22,'7.4 (P)'!O22) -> 80 | P22: =SUM('7.4 (L)'!P22,'7.4 (P)'!P22) -> 57 | Q22: =SUM('7.4 (L)'!Q22,'7.4 (P)'!Q22) -> 27
B24: Kedah | D24: 2021 | E24: =SUM('7.4 (L)'!E24,'7.4 (P)'!E24) -> 28 | F24: =SUM('7.4 (L)'!F24,'7.4 (P)'!F24) -> 103 | G24: =SUM('7.4 (L)'!G24,'7.4 (P)'!G24) -> 75 | H24: =SUM('7.4 (L)'!H24,'7.4 (P)'!H24) -> 76 | I24: =SUM('7.4 (L)'!I24,'7.4 (P)'!I24) -> 63 | J24: =SUM('7.4 (L)'!J24,'7.4 (P)'!J24) -> 28 | L24: =SUM('7.4 (L)'!L24,'7.4 (P)'!L24) -> 4 | M24: =SUM('7.4 (L)'!M24,'7.4 (P)'!M24) -> 19 | N24: =SUM('7.4 (L)'!N24,'7.4 (P)'!N24) -> 8 | O24: =SUM('7.4 (L)'!O24,'7.4 (P)'!O24) -> 9 | P24: =SUM('7.4 (L)'!P24,'7.4 (P)'!P24) -> 8 | Q24: =SUM('7.4 (L)'!Q24,'7.4 (P)'!Q24) -> 5
D25: 2022 | E25: =SUM('7.4 (L)'!E25,'7.4 (P)'!E25) -> 27 | F25: =SUM('7.4 (L)'!F25,'7.4 (P)'!F25) -> 118 | G25: =SUM('7.4 (L)'!G25,'7.4 (P)'!G25) -> 108 | H25: =SUM('7.4 (L)'!H25,'7.4 (P)'!H25) -> 105 | I25: =SUM('7.4 (L)'!I25,'7.4 (P)'!I25) -> 63 | J25: =SUM('7.4 (L)'!J25,'7.4 (P)'!J25) -> 53 | L25: =SUM('7.4 (L)'!L25,'7.4 (P)'!L25) -> 2 | M25: =SUM('7.4 (L)'!M25,'7.4 (P)'!M25) -> 11 | N25: =SUM('7.4 (L)'!N25,'7.4 (P)'!N25) -> 12 | O25: =SUM('7.4 (L)'!O25,'7.4 (P)'!O25) -> 13 | P25: =SUM('7.4 (L)'!P25,'7.4 (P)'!P25) -> 9 | Q25: =SUM('7.4 (L)'!Q25,'7.4 (P)'!Q25) -> 9
D26: 2023 | E26: =SUM('7.4 (L)'!E26,'7.4 (P)'!E26) -> 37 | F26: =SUM('7.4 (L)'!F26,'7.4 (P)'!F26) -> 170 | G26: =SUM('7.4 (L)'!G26,'7.4 (P)'!G26) -> 113 | H26: =SUM('7.4 (L)'!H26,'7.4 (P)'!H26) -> 106 | I26: =SUM('7.4 (L)'!I26,'7.4 (P)'!I26) -> 80 | J26: =SUM('7.4 (L)'!J26,'7.4 (P)'!J26) -> 47 | L26: =SUM('7.4 (L)'!L26,'7.4 (P)'!L26) -> 9 | M26: =SUM('7.4 (L)'!M26,'7.4 (P)'!M26) -> 25 | N26: =SUM('7.4 (L)'!N26,'7.4 (P)'!N26) -> 26 | O26: =SUM('7.4 (L)'!O26,'7.4 (P)'!O26) -> 16 | P26: =SUM('7.4 (L)'!P26,'7.4 (P)'!P26) -> 18 | Q26: =SUM('7.4 (L)'!Q26,'7.4 (P)'!Q26) -> 11
B28: Kelantan | D28: 2021 | E28: =SUM('7.4 (L)'!E28,'7.4 (P)'!E28) -> 13 | F28: =SUM('7.4 (L)'!F28,'7.4 (P)'!F28) -> 39 | G28: =SUM('7.4 (L)'!G28,'7.4 (P)'!G28) -> 28 | H28: =SUM('7.4 (L)'!H28,'7.4 (P)'!H28) -> 26 | I28: =SUM('7.4 (L)'!I28,'7.4 (P)'!I28) -> 14 | J28: =SUM('7.4 (L)'!J28,'7.4 (P)'!J28) -> 11 | L28: =SUM('7.4 (L)'!L28,'7.4 (P)'!L28) -> 3 | M28: =SUM('7.4 (L)'!M28,'7.4 (P)'!M28) -> 13 | N28: =SUM('7.4 (L)'!N28,'7.4 (P)'!N28) -> 10 | O28: =SUM('7.4 (L)'!O28,'7.4 (P)'!O28) -> 6 | P28: =SUM('7.4 (L)'!P28,'7.4 (P)'!P28) -> 7 | Q28: =SUM('7.4 (L)'!Q28,'7.4 (P)'!Q28) -> 2
D29: 2022 | E29: =SUM('7.4 (L)'!E29,'7.4 (P)'!E29) -> 7 | F29: =SUM('7.4 (L)'!F29,'7.4 (P)'!F29) -> 76 | G29: =SUM('7.4 (L)'!G29,'7.4 (P)'!G29) -> 65 | H29: =SUM('7.4 (L)'!H29,'7.4 (P)'!H29) -> 56 | I29: =SUM('7.4 (L)'!I29,'7.4 (P)'!I29) -> 42 | J29: =SUM('7.4 (L)'!J29,'7.4 (P)'!J29) -> 21 | L29: =SUM('7.4 (L)'!L29,'7.4 (P)'!L29) -> 3 | M29: =SUM('7.4 (L)'!M29,'7.4 (P)'!M29) -> 11 | N29: =SUM('7.4 (L)'!N29,'7.4 (P)'!N29) -> 13 | O29: =SUM('7.4 (L)'!O29,'7.4 (P)'!O29) -> 13 | P29: =SUM('7.4 (L)'!P29,'7.4 (P)'!P29) -> 4 | Q29: =SUM('7.4 (L)'!Q29,'7.4 (P)'!Q29) -> 4
D30: 2023 | E30: =SUM('7.4 (L)'!E30,'7.4 (P)'!E30) -> 16 | F30: =SUM('7.4 (L)'!F30,'7.4 (P)'!F30) -> 80 | G30: =SUM('7.4 (L)'!G30,'7.4 (P)'!G30) -> 73 | H30: =SUM('7.4 (L)'!H30,'7.4 (P)'!H30) -> 49 | I30: =SUM('7.4 (L)'!I30,'7.4 (P)'!I30) -> 58 | J30: =SUM('7.4 (L)'!J30,'7.4 (P)'!J30) -> 47 | L30: =SUM('7.4 (L)'!L30,'7.4 (P)'!L30) -> 2 | M30: =SUM('7.4 (L)'!M30,'7.4 (P)'!M30) -> 9 | N30: =SUM('7.4 (L)'!N30,'7.4 (P)'!N30) -> 10 | O30: =SUM('7.4 (L)'!O30,'7.4 (P)'!O30) -> 11 | P30: =SUM('7.4 (L)'!P30,'7.4 (P)'!P30) -> 5 | Q30: =SUM('7.4 (L)'!Q30,'7.4 (P)'!Q30) -> 8
B32: Melaka | D32: 2021 | E32: =SUM('7.4 (L)'!E32,'7.4 (P)'!E32) -> 10 | F32: =SUM('7.4 (L)'!F32,'7.4 (P)'!F32) -> 62 | G32: =SUM('7.4 (L)'!G32,'7.4 (P)'!G32) -> 58 | H32: =SUM('7.4 (L)'!H32,'7.4 (P)'!H32) -> 57 | I32: =SUM('7.4 (L)'!I32,'7.4 (P)'!I32) -> 41 | J32: =SUM('7.4 (L)'!J32,'7.4 (P)'!J32) -> 41 | L32: =SUM('7.4 (L)'!L32,'7.4 (P)'!L32) -> 3 | M32: =SUM('7.4 (L)'!M32,'7.4 (P)'!M32) -> 11 | N32: =SUM('7.4 (L)'!N32,'7.4 (P)'!N32) -> 8 | O32: =SUM('7.4 (L)'!O32,'7.4 (P)'!O32) -> 6 | P32: =SUM('7.4 (L)'!P32,'7.4 (P)'!P32) -> 6 | Q32: =SUM('7.4 (L)'!Q32,'7.4 (P)'!Q32) -> 4
D33: 2022 | E33: =SUM('7.4 (L)'!E33,'7.4 (P)'!E33) -> 18 | F33: =SUM('7.4 (L)'!F33,'7.4 (P)'!F33) -> 112 | G33: =SUM('7.4 (L)'!G33,'7.4 (P)'!G33) -> 90 | H33: =SUM('7.4 (L)'!H33,'7.4 (P)'!H33) -> 65 | I33: =SUM('7.4 (L)'!I33,'7.4 (P)'!I33) -> 53 | J33: =SUM('7.4 (L)'!J33,'7.4 (P)'!J33) -> 43 | L33: =SUM('7.4 (L)'!L33,'7.4 (P)'!L33) -> 3 | M33: =SUM('7.4 (L)'!M33,'7.4 (P)'!M33) -> 6 | N33: =SUM('7.4 (L)'!N33,'7.4 (P)'!N33) -> 18 | O33: =SUM('7.4 (L)'!O33,'7.4 (P)'!O33) -> 11 | P33: =SUM('7.4 (L)'!P33,'7.4 (P)'!P33) -> 12 | Q33: =SUM('7.4 (L)'!Q33,'7.4 (P)'!Q33) -> 2
D34: 2023 | E34: =SUM('7.4 (L)'!E34,'7.4 (P)'!E34) -> 33 | F34: =SUM('7.4 (L)'!F34,'7.4 (P)'!F34) -> 124 | G34: =SUM('7.4 (L)'!G34,'7.4 (P)'!G34) -> 74 | H34: =SUM('7.4 (L)'!H34,'7.4 (P)'!H34) -> 56 | I34: =SUM('7.4 (L)'!I34,'7.4 (P)'!I34) -> 53 | J34: =SUM('7.4 (L)'!J34,'7.4 (P)'!J34) -> 27 | L34: =SUM('7.4 (L)'!L34,'7.4 (P)'!L34) -> 9 | M34: =SUM('7.4 (L)'!M34,'7.4 (P)'!M34) -> 20 | N34: =SUM('7.4 (L)'!N34,'7.4 (P)'!N34) -> 17 | O34: =SUM('7.4 (L)'!O34,'7.4 (P)'!O34) -> 14 | P34: =SUM('7.4 (L)'!P34,'7.4 (P)'!P34) -> 10 | Q34: =SUM('7.4 (L)'!Q34,'7.4 (P)'!Q34) -> 7
B36: Negeri Sembilan | D36: 2021 | E36: =SUM('7.4 (L)'!E36,'7.4 (P)'!E36) -> 30 | F36: =SUM('7.4 (L)'!F36,'7.4 (P)'!F36) -> 202 | G36: =SUM('7.4 (L)'!G36,'7.4 (P)'!G36) -> 129 | H36: =SUM('7.4 (L)'!H36,'7.4 (P)'!H36) -> 93 | I36: =SUM('7.4 (L)'!I36,'7.4 (P)'!I36) -> 55 | J36: =SUM('7.4 (L)'!J36,'7.4 (P)'!J36) -> 56 | L36: =SUM('7.4 (L)'!L36,'7.4 (P)'!L36) -> 13 | M36: =SUM('7.4 (L)'!M36,'7.4 (P)'!M36) -> 39 | N36: =SUM('7.4 (L)'!N36,'7.4 (P)'!N36) -> 17 | O36: =SUM('7.4 (L)'!O36,'7.4 (P)'!O36) -> 13 | P36: =SUM('7.4 (L)'!P36,'7.4 (P)'!P36) -> 7 | Q36: =SUM('7.4 (L)'!Q36,'7.4 (P)'!Q36) -> 6
D37: 2022 | E37: =SUM('7.4 (L)'!E37,'7.4 (P)'!E37) -> 72 | F37: =SUM('7.4 (L)'!F37,'7.4 (P)'!F37) -> 294 | G37: =SUM('7.4 (L)'!G37,'7.4 (P)'!G37) -> 210 | H37: =SUM('7.4 (L)'!H37,'7.4 (P)'!H37) -> 139 | I37: =SUM('7.4 (L)'!I37,'7.4 (P)'!I37) -> 103 | J37: =SUM('7.4 (L)'!J37,'7.4 (P)'!J37) -> 65 | L37: =SUM('7.4 (L)'!L37,'7.4 (P)'!L37) -> 15 | M37: =SUM('7.4 (L)'!M37,'7.4 (P)'!M37) -> 23 | N37: =SUM('7.4 (L)'!N37,'7.4 (P)'!N37) -> 43 | O37: =SUM('7.4 (L)'!O37,'7.4 (P)'!O37) -> 30 | P37: =SUM('7.4 (L)'!P37,'7.4 (P)'!P37) -> 14 | Q37: =SUM('7.4 (L)'!Q37,'7.4 (P)'!Q37) -> 8
D38: 2023 | E38: =SUM('7.4 (L)'!E38,'7.4 (P)'!E38) -> 54 | F38: =SUM('7.4 (L)'!F38,'7.4 (P)'!F38) -> 230 | G38: =SUM('7.4 (L)'!G38,'7.4 (P)'!G38) -> 139 | H38: =SUM('7.4 (L)'!H38,'7.4 (P)'!H38) -> 113 | I38: =SUM('7.4 (L)'!I38,'7.4 (P)'!I38) -> 97 | J38: =SUM('7.4 (L)'!J38,'7.4 (P)'!J38) -> 75 | L38: =SUM('7.4 (L)'!L38,'7.4 (P)'!L38) -> 14 | M38: =SUM('7.4 (L)'!M38,'7.4 (P)'!M38) -> 41 | N38: =SUM('7.4 (L)'!N38,'7.4 (P)'!N38) -> 32 | O38: =SUM('7.4 (L)'!O38,'7.4 (P)'!O38) -> 33 | P38: =SUM('7.4 (L)'!P38,'7.4 (P)'!P38) -> 20 | Q38: =SUM('7.4 (L)'!Q38,'7.4 (P)'!Q38) -> 16
B40: Pahang | D40: 2021 | E40: =SUM('7.4 (L)'!E40,'7.4 (P)'!E40) -> 18 | F40: =SUM('7.4 (L)'!F40,'7.4 (P)'!F40) -> 84 | G40: =SUM('7.4 (L)'!G40,'7.4 (P)'!G40) -> 62 | H40: =SUM('7.4 (L)'!H40,'7.4 (P)'!H40) -> 49 | I40: =SUM('7.4 (L)'!I40,'7.4 (P)'!I40) -> 41 | J40: =SUM('7.4 (L)'!J40,'7.4 (P)'!J40) -> 31 | L40: =SUM('7.4 (L)'!L40,'7.4 (P)'!L40) -> 4 | M40: =SUM('7.4 (L)'!M40,'7.4 (P)'!M40) -> 5 | N40: =SUM('7.4 (L)'!N40,'7.4 (P)'!N40) -> 7 | O40: =SUM('7.4 (L)'!O40,'7.4 (P)'!O40) -> 6 | P40: =SUM('7.4 (L)'!P40,'7.4 (P)'!P40) -> 6 | Q40: =SUM('7.4 (L)'!Q40,'7.4 (P)'!Q40) -> 5
D41: 2022 | E41: =SUM('7.4 (L)'!E41,'7.4 (P)'!E41) -> 15 | F41: =SUM('7.4 (L)'!F41,'7.4 (P)'!F41) -> 152 | G41: =SUM('7.4 (L)'!G41,'7.4 (P)'!G41) -> 124 | H41: =SUM('7.4 (L)'!H41,'7.4 (P)'!H41) -> 86 | I41: =SUM('7.4 (L)'!I41,'7.4 (P)'!I41) -> 66 | J41: =SUM('7.4 (L)'!J41,'7.4 (P)'!J41) -> 51 | L41: =SUM('7.4 (L)'!L41,'7.4 (P)'!L41) -> 2 | M41: =SUM('7.4 (L)'!M41,'7.4 (P)'!M41) -> 11 | N41: =SUM('7.4 (L)'!N41,'7.4 (P)'!N41) -> 13 | O41: =SUM('7.4 (L)'!O41,'7.4 (P)'!O41) -> 7 | P41: =SUM('7.4 (L)'!P41,'7.4 (P)'!P41) -> 12 | Q41: =SUM('7.4 (L)'!Q41,'7.4 (P)'!Q41) -> 3
D42: 2023 | E42: =SUM('7.4 (L)'!E42,'7.4 (P)'!E42) -> 49 | F42: =SUM('7.4 (L)'!F42,'7.4 (P)'!F42) -> 156 | G42: =SUM('7.4 (L)'!G42,'7.4 (P)'!G42) -> 125 | H42: =SUM('7.4 (L)'!H42,'7.4 (P)'!H42) -> 95 | I42: =SUM('7.4 (L)'!I42,'7.4 (P)'!I42) -> 74 | J42: =SUM('7.4 (L)'!J42,'7.4 (P)'!J42) -> 63 | L42: =SUM('7.4 (L)'!L42,'7.4 (P)'!L42) -> 3 | M42: =SUM('7.4 (L)'!M42,'7.4 (P)'!M42) -> 18 | N42: =SUM('7.4 (L)'!N42,'7.4 (P)'!N42) -> 32 | O42: =SUM('7.4 (L)'!O42,'7.4 (P)'!O42) -> 17 | P42: =SUM('7.4 (L)'!P42,'7.4 (P)'!P42) -> 13 | Q42: =SUM('7.4 (L)'!Q42,'7.4 (P)'!Q42) -> 4
B44: Pulau Pinang | D44: 2021 | E44: =SUM('7.4 (L)'!E44,'7.4 (P)'!E44) -> 54 | F44: =SUM('7.4 (L)'!F44,'7.4 (P)'!F44) -> 254 | G44: =SUM('7.4 (L)'!G44,'7.4 (P)'!G44) -> 191 | H44: =SUM('7.4 (L)'!H44,'7.4 (P)'!H44) -> 127 | I44: =SUM('7.4 (L)'!I44,'7.4 (P)'!I44) -> 113 | J44: =SUM('7.4 (L)'!J44,'7.4 (P)'!J44) -> 90 | L44: =SUM('7.4 (L)'!L44,'7.4 (P)'!L44) -> 7 | M44: =SUM('7.4 (L)'!M44,'7.4 (P)'!M44) -> 18 | N44: =SUM('7.4 (L)'!N44,'7.4 (P)'!N44) -> 12 | O44: =SUM('7.4 (L)'!O44,'7.4 (P)'!O44) -> 16 | P44: =SUM('7.4 (L)'!P44,'7.4 (P)'!P44) -> 10 | Q44: =SUM('7.4 (L)'!Q44,'7.4 (P)'!Q44) -> 3
D45: 2022 | E45: =SUM('7.4 (L)'!E45,'7.4 (P)'!E45) -> 31 | F45: =SUM('7.4 (L)'!F45,'7.4 (P)'!F45) -> 228 | G45: =SUM('7.4 (L)'!G45,'7.4 (P)'!G45) -> 156 | H45: =SUM('7.4 (L)'!H45,'7.4 (P)'!H45) -> 128 | I45: =SUM('7.4 (L)'!I45,'7.4 (P)'!I45) -> 108 | J45: =SUM('7.4 (L)'!J45,'7.4 (P)'!J45) -> 67 | L45: =SUM('7.4 (L)'!L45,'7.4 (P)'!L45) -> 5 | M45: =SUM('7.4 (L)'!M45,'7.4 (P)'!M45) -> 19 | N45: =SUM('7.4 (L)'!N45,'7.4 (P)'!N45) -> 26 | O45: =SUM('7.4 (L)'!O45,'7.4 (P)'!O45) -> 23 | P45: =SUM('7.4 (L)'!P45,'7.4 (P)'!P45) -> 14 | Q45: =SUM('7.4 (L)'!Q45,'7.4 (P)'!Q45) -> 6
D46: 2023 | E46: =SUM('7.4 (L)'!E46,'7.4 (P)'!E46) -> 56 | F46: =SUM('7.4 (L)'!F46,'7.4 (P)'!F46) -> 314 | G46: =SUM('7.4 (L)'!G46,'7.4 (P)'!G46) -> 193 | H46: =SUM('7.4 (L)'!H46,'7.4 (P)'!H46) -> 173 | I46: =SUM('7.4 (L)'!I46,'7.4 (P)'!I46) -> 115 | J46: =SUM('7.4 (L)'!J46,'7.4 (P)'!J46) -> 98 | L46: =SUM('7.4 (L)'!L46,'7.4 (P)'!L46) -> 6 | M46: =SUM('7.4 (L)'!M46,'7.4 (P)'!M46) -> 20 | N46: =SUM('7.4 (L)'!N46,'7.4 (P)'!N46) -> 30 | O46: =SUM('7.4 (L)'!O46,'7.4 (P)'!O46) -> 47 | P46: =SUM('7.4 (L)'!P46,'7.4 (P)'!P46) -> 20 | Q46: =SUM('7.4 (L)'!Q46,'7.4 (P)'!Q46) -> 11
B48: Perak | D48: 2021 | E48: =SUM('7.4 (L)'!E48,'7.4 (P)'!E48) -> 24 | F48: =SUM('7.4 (L)'!F48,'7.4 (P)'!F48) -> 120 | G48: =SUM('7.4 (L)'!G48,'7.4 (P)'!G48) -> 81 | H48: =SUM('7.4 (L)'!H48,'7.4 (P)'!H48) -> 57 | I48: =SUM('7.4 (L)'!I48,'7.4 (P)'!I48) -> 73 | J48: =SUM('7.4 (L)'!J48,'7.4 (P)'!J48) -> 77 | L48: =SUM('7.4 (L)'!L48,'7.4 (P)'!L48) -> 0 | M48: =SUM('7.4 (L)'!M48,'7.4 (P)'!M48) -> 15 | N48: =SUM('7.4 (L)'!N48,'7.4 (P)'!N48) -> 12 | O48: =SUM('7.4 (L)'!O48,'7.4 (P)'!O48) -> 4 | P48: =SUM('7.4 (L)'!P48,'7.4 (P)'!P48) -> 8 | Q48: =SUM('7.4 (L)'!Q48,'7.4 (P)'!Q48) -> 4
D49: 2022 | E49: =SUM('7.4 (L)'!E49,'7.4 (P)'!E49) -> 38 | F49: =SUM('7.4 (L)'!F49,'7.4 (P)'!F49) -> 129 | G49: =SUM('7.4 (L)'!G49,'7.4 (P)'!G49) -> 126 | H49: =SUM('7.4 (L)'!H49,'7.4 (P)'!H49) -> 106 | I49: =SUM('7.4 (L)'!I49,'7.4 (P)'!I49) -> 73 | J49: =SUM('7.4 (L)'!J49,'7.4 (P)'!J49) -> 63 | L49: =SUM('7.4 (L)'!L49,'7.4 (P)'!L49) -> 3 | M49: =SUM('7.4 (L)'!M49,'7.4 (P)'!M49) -> 14 | N49: =SUM('7.4 (L)'!N49,'7.4 (P)'!N49) -> 11 | O49: =SUM('7.4 (L)'!O49,'7.4 (P)'!O49) -> 17 | P49: =SUM('7.4 (L)'!P49,'7.4 (P)'!P49) -> 9 | Q49: =SUM('7.4 (L)'!Q49,'7.4 (P)'!Q49) -> 8
